package net.minecraft.structure.generator;

import com.google.common.collect.ImmutableSet;
import com.google.common.collect.Lists;
import java.util.Collections;
import java.util.List;
import java.util.Random;
import java.util.Set;
import net.minecraft.block.Block;
import net.minecraft.block.BlockState;
import net.minecraft.block.Blocks;
import net.minecraft.entity.EntityType;
import net.minecraft.entity.SpawnType;
import net.minecraft.entity.mob.ElderGuardianEntity;
import net.minecraft.nbt.CompoundTag;
import net.minecraft.structure.StructureManager;
import net.minecraft.structure.StructurePiece;
import net.minecraft.structure.StructurePieceType;
import net.minecraft.util.math.BlockPos;
import net.minecraft.util.math.Direction;
import net.minecraft.util.math.MutableIntBoundingBox;
import net.minecraft.world.IWorld;
import net.minecraft.world.chunk.ChunkPos;

public class OceanMonumentGenerator {
	public static class Entry extends OceanMonumentGenerator.class_3384 {
		public Entry(Direction direction, OceanMonumentGenerator.class_3388 arg) {
			super(StructurePieceType.OCEAN_MONUMENT_ENTRY, 1, direction, arg, 1, 1, 1);
		}

		public Entry(StructureManager structureManager, CompoundTag compoundTag) {
			super(StructurePieceType.OCEAN_MONUMENT_ENTRY, compoundTag);
		}

		@Override
		public boolean generate(IWorld iWorld, Random random, MutableIntBoundingBox mutableIntBoundingBox, ChunkPos chunkPos) {
			this.fillWithOutline(iWorld, mutableIntBoundingBox, 0, 3, 0, 2, 3, 7, field_14476, field_14476, false);
			this.fillWithOutline(iWorld, mutableIntBoundingBox, 5, 3, 0, 7, 3, 7, field_14476, field_14476, false);
			this.fillWithOutline(iWorld, mutableIntBoundingBox, 0, 2, 0, 1, 2, 7, field_14476, field_14476, false);
			this.fillWithOutline(iWorld, mutableIntBoundingBox, 6, 2, 0, 7, 2, 7, field_14476, field_14476, false);
			this.fillWithOutline(iWorld, mutableIntBoundingBox, 0, 1, 0, 0, 1, 7, field_14476, field_14476, false);
			this.fillWithOutline(iWorld, mutableIntBoundingBox, 7, 1, 0, 7, 1, 7, field_14476, field_14476, false);
			this.fillWithOutline(iWorld, mutableIntBoundingBox, 0, 1, 7, 7, 3, 7, field_14476, field_14476, false);
			this.fillWithOutline(iWorld, mutableIntBoundingBox, 1, 1, 0, 2, 3, 0, field_14476, field_14476, false);
			this.fillWithOutline(iWorld, mutableIntBoundingBox, 5, 1, 0, 6, 3, 0, field_14476, field_14476, false);
			if (this.field_14479.field_14482[Direction.NORTH.getId()]) {
				this.method_14773(iWorld, mutableIntBoundingBox, 3, 1, 7, 4, 2, 7);
			}

			if (this.field_14479.field_14482[Direction.WEST.getId()]) {
				this.method_14773(iWorld, mutableIntBoundingBox, 0, 1, 3, 1, 2, 4);
			}

			if (this.field_14479.field_14482[Direction.EAST.getId()]) {
				this.method_14773(iWorld, mutableIntBoundingBox, 6, 1, 3, 7, 2, 4);
			}

			return true;
		}
	}

	public static class Penthouse extends OceanMonumentGenerator.class_3384 {
		public Penthouse(Direction direction, MutableIntBoundingBox mutableIntBoundingBox) {
			super(StructurePieceType.OCEAN_MONUMENT_PENTHOUSE, direction, mutableIntBoundingBox);
		}

		public Penthouse(StructureManager structureManager, CompoundTag compoundTag) {
			super(StructurePieceType.OCEAN_MONUMENT_PENTHOUSE, compoundTag);
		}

		@Override
		public boolean generate(IWorld iWorld, Random random, MutableIntBoundingBox mutableIntBoundingBox, ChunkPos chunkPos) {
			this.fillWithOutline(iWorld, mutableIntBoundingBox, 2, -1, 2, 11, -1, 11, field_14476, field_14476, false);
			this.fillWithOutline(iWorld, mutableIntBoundingBox, 0, -1, 0, 1, -1, 11, field_14473, field_14473, false);
			this.fillWithOutline(iWorld, mutableIntBoundingBox, 12, -1, 0, 13, -1, 11, field_14473, field_14473, false);
			this.fillWithOutline(iWorld, mutableIntBoundingBox, 2, -1, 0, 11, -1, 1, field_14473, field_14473, false);
			this.fillWithOutline(iWorld, mutableIntBoundingBox, 2, -1, 12, 11, -1, 13, field_14473, field_14473, false);
			this.fillWithOutline(iWorld, mutableIntBoundingBox, 0, 0, 0, 0, 0, 13, field_14476, field_14476, false);
			this.fillWithOutline(iWorld, mutableIntBoundingBox, 13, 0, 0, 13, 0, 13, field_14476, field_14476, false);
			this.fillWithOutline(iWorld, mutableIntBoundingBox, 1, 0, 0, 12, 0, 0, field_14476, field_14476, false);
			this.fillWithOutline(iWorld, mutableIntBoundingBox, 1, 0, 13, 12, 0, 13, field_14476, field_14476, false);

			for (int i = 2; i <= 11; i += 3) {
				this.addBlock(iWorld, field_14471, 0, 0, i, mutableIntBoundingBox);
				this.addBlock(iWorld, field_14471, 13, 0, i, mutableIntBoundingBox);
				this.addBlock(iWorld, field_14471, i, 0, 0, mutableIntBoundingBox);
			}

			this.fillWithOutline(iWorld, mutableIntBoundingBox, 2, 0, 3, 4, 0, 9, field_14476, field_14476, false);
			this.fillWithOutline(iWorld, mutableIntBoundingBox, 9, 0, 3, 11, 0, 9, field_14476, field_14476, false);
			this.fillWithOutline(iWorld, mutableIntBoundingBox, 4, 0, 9, 9, 0, 11, field_14476, field_14476, false);
			this.addBlock(iWorld, field_14476, 5, 0, 8, mutableIntBoundingBox);
			this.addBlock(iWorld, field_14476, 8, 0, 8, mutableIntBoundingBox);
			this.addBlock(iWorld, field_14476, 10, 0, 10, mutableIntBoundingBox);
			this.addBlock(iWorld, field_14476, 3, 0, 10, mutableIntBoundingBox);
			this.fillWithOutline(iWorld, mutableIntBoundingBox, 3, 0, 3, 3, 0, 7, field_14474, field_14474, false);
			this.fillWithOutline(iWorld, mutableIntBoundingBox, 10, 0, 3, 10, 0, 7, field_14474, field_14474, false);
			this.fillWithOutline(iWorld, mutableIntBoundingBox, 6, 0, 10, 7, 0, 10, field_14474, field_14474, false);
			int i = 3;

			for (int j = 0; j < 2; j++) {
				for (int k = 2; k <= 8; k += 3) {
					this.fillWithOutline(iWorld, mutableIntBoundingBox, i, 0, k, i, 2, k, field_14476, field_14476, false);
				}

				i = 10;
			}

			this.fillWithOutline(iWorld, mutableIntBoundingBox, 5, 0, 10, 5, 2, 10, field_14476, field_14476, false);
			this.fillWithOutline(iWorld, mutableIntBoundingBox, 8, 0, 10, 8, 2, 10, field_14476, field_14476, false);
			this.fillWithOutline(iWorld, mutableIntBoundingBox, 6, -1, 7, 7, -1, 8, field_14474, field_14474, false);
			this.method_14773(iWorld, mutableIntBoundingBox, 6, -1, 3, 7, -1, 4);
			this.method_14772(iWorld, mutableIntBoundingBox, 6, 1, 6);
			return true;
		}
	}

	public static class SimpleRoom extends OceanMonumentGenerator.class_3384 {
		private int field_14480;

		public SimpleRoom(Direction direction, OceanMonumentGenerator.class_3388 arg, Random random) {
			super(StructurePieceType.OCEAN_MONUMENT_SIMPLE_ROOM, 1, direction, arg, 1, 1, 1);
			this.field_14480 = random.nextInt(3);
		}

		public SimpleRoom(StructureManager structureManager, CompoundTag compoundTag) {
			super(StructurePieceType.OCEAN_MONUMENT_SIMPLE_ROOM, compoundTag);
		}

		@Override
		public boolean generate(IWorld iWorld, Random random, MutableIntBoundingBox mutableIntBoundingBox, ChunkPos chunkPos) {
			if (this.field_14479.field_14486 / 25 > 0) {
				this.method_14774(iWorld, mutableIntBoundingBox, 0, 0, this.field_14479.field_14482[Direction.DOWN.getId()]);
			}

			if (this.field_14479.field_14487[Direction.UP.getId()] == null) {
				this.method_14771(iWorld, mutableIntBoundingBox, 1, 4, 1, 6, 4, 6, field_14473);
			}

			boolean bl = this.field_14480 != 0
				&& random.nextBoolean()
				&& !this.field_14479.field_14482[Direction.DOWN.getId()]
				&& !this.field_14479.field_14482[Direction.UP.getId()]
				&& this.field_14479.method_14781() > 1;
			if (this.field_14480 == 0) {
				this.fillWithOutline(iWorld, mutableIntBoundingBox, 0, 1, 0, 2, 1, 2, field_14476, field_14476, false);
				this.fillWithOutline(iWorld, mutableIntBoundingBox, 0, 3, 0, 2, 3, 2, field_14476, field_14476, false);
				this.fillWithOutline(iWorld, mutableIntBoundingBox, 0, 2, 0, 0, 2, 2, field_14473, field_14473, false);
				this.fillWithOutline(iWorld, mutableIntBoundingBox, 1, 2, 0, 2, 2, 0, field_14473, field_14473, false);
				this.addBlock(iWorld, field_14471, 1, 2, 1, mutableIntBoundingBox);
				this.fillWithOutline(iWorld, mutableIntBoundingBox, 5, 1, 0, 7, 1, 2, field_14476, field_14476, false);
				this.fillWithOutline(iWorld, mutableIntBoundingBox, 5, 3, 0, 7, 3, 2, field_14476, field_14476, false);
				this.fillWithOutline(iWorld, mutableIntBoundingBox, 7, 2, 0, 7, 2, 2, field_14473, field_14473, false);
				this.fillWithOutline(iWorld, mutableIntBoundingBox, 5, 2, 0, 6, 2, 0, field_14473, field_14473, false);
				this.addBlock(iWorld, field_14471, 6, 2, 1, mutableIntBoundingBox);
				this.fillWithOutline(iWorld, mutableIntBoundingBox, 0, 1, 5, 2, 1, 7, field_14476, field_14476, false);
				this.fillWithOutline(iWorld, mutableIntBoundingBox, 0, 3, 5, 2, 3, 7, field_14476, field_14476, false);
				this.fillWithOutline(iWorld, mutableIntBoundingBox, 0, 2, 5, 0, 2, 7, field_14473, field_14473, false);
				this.fillWithOutline(iWorld, mutableIntBoundingBox, 1, 2, 7, 2, 2, 7, field_14473, field_14473, false);
				this.addBlock(iWorld, field_14471, 1, 2, 6, mutableIntBoundingBox);
				this.fillWithOutline(iWorld, mutableIntBoundingBox, 5, 1, 5, 7, 1, 7, field_14476, field_14476, false);
				this.fillWithOutline(iWorld, mutableIntBoundingBox, 5, 3, 5, 7, 3, 7, field_14476, field_14476, false);
				this.fillWithOutline(iWorld, mutableIntBoundingBox, 7, 2, 5, 7, 2, 7, field_14473, field_14473, false);
				this.fillWithOutline(iWorld, mutableIntBoundingBox, 5, 2, 7, 6, 2, 7, field_14473, field_14473, false);
				this.addBlock(iWorld, field_14471, 6, 2, 6, mutableIntBoundingBox);
				if (this.field_14479.field_14482[Direction.SOUTH.getId()]) {
					this.fillWithOutline(iWorld, mutableIntBoundingBox, 3, 3, 0, 4, 3, 0, field_14476, field_14476, false);
				} else {
					this.fillWithOutline(iWorld, mutableIntBoundingBox, 3, 3, 0, 4, 3, 1, field_14476, field_14476, false);
					this.fillWithOutline(iWorld, mutableIntBoundingBox, 3, 2, 0, 4, 2, 0, field_14473, field_14473, false);
					this.fillWithOutline(iWorld, mutableIntBoundingBox, 3, 1, 0, 4, 1, 1, field_14476, field_14476, false);
				}

				if (this.field_14479.field_14482[Direction.NORTH.getId()]) {
					this.fillWithOutline(iWorld, mutableIntBoundingBox, 3, 3, 7, 4, 3, 7, field_14476, field_14476, false);
				} else {
					this.fillWithOutline(iWorld, mutableIntBoundingBox, 3, 3, 6, 4, 3, 7, field_14476, field_14476, false);
					this.fillWithOutline(iWorld, mutableIntBoundingBox, 3, 2, 7, 4, 2, 7, field_14473, field_14473, false);
					this.fillWithOutline(iWorld, mutableIntBoundingBox, 3, 1, 6, 4, 1, 7, field_14476, field_14476, false);
				}

				if (this.field_14479.field_14482[Direction.WEST.getId()]) {
					this.fillWithOutline(iWorld, mutableIntBoundingBox, 0, 3, 3, 0, 3, 4, field_14476, field_14476, false);
				} else {
					this.fillWithOutline(iWorld, mutableIntBoundingBox, 0, 3, 3, 1, 3, 4, field_14476, field_14476, false);
					this.fillWithOutline(iWorld, mutableIntBoundingBox, 0, 2, 3, 0, 2, 4, field_14473, field_14473, false);
					this.fillWithOutline(iWorld, mutableIntBoundingBox, 0, 1, 3, 1, 1, 4, field_14476, field_14476, false);
				}

				if (this.field_14479.field_14482[Direction.EAST.getId()]) {
					this.fillWithOutline(iWorld, mutableIntBoundingBox, 7, 3, 3, 7, 3, 4, field_14476, field_14476, false);
				} else {
					this.fillWithOutline(iWorld, mutableIntBoundingBox, 6, 3, 3, 7, 3, 4, field_14476, field_14476, false);
					this.fillWithOutline(iWorld, mutableIntBoundingBox, 7, 2, 3, 7, 2, 4, field_14473, field_14473, false);
					this.fillWithOutline(iWorld, mutableIntBoundingBox, 6, 1, 3, 7, 1, 4, field_14476, field_14476, false);
				}
			} else if (this.field_14480 == 1) {
				this.fillWithOutline(iWorld, mutableIntBoundingBox, 2, 1, 2, 2, 3, 2, field_14476, field_14476, false);
				this.fillWithOutline(iWorld, mutableIntBoundingBox, 2, 1, 5, 2, 3, 5, field_14476, field_14476, false);
				this.fillWithOutline(iWorld, mutableIntBoundingBox, 5, 1, 5, 5, 3, 5, field_14476, field_14476, false);
				this.fillWithOutline(iWorld, mutableIntBoundingBox, 5, 1, 2, 5, 3, 2, field_14476, field_14476, false);
				this.addBlock(iWorld, field_14471, 2, 2, 2, mutableIntBoundingBox);
				this.addBlock(iWorld, field_14471, 2, 2, 5, mutableIntBoundingBox);
				this.addBlock(iWorld, field_14471, 5, 2, 5, mutableIntBoundingBox);
				this.addBlock(iWorld, field_14471, 5, 2, 2, mutableIntBoundingBox);
				this.fillWithOutline(iWorld, mutableIntBoundingBox, 0, 1, 0, 1, 3, 0, field_14476, field_14476, false);
				this.fillWithOutline(iWorld, mutableIntBoundingBox, 0, 1, 1, 0, 3, 1, field_14476, field_14476, false);
				this.fillWithOutline(iWorld, mutableIntBoundingBox, 0, 1, 7, 1, 3, 7, field_14476, field_14476, false);
				this.fillWithOutline(iWorld, mutableIntBoundingBox, 0, 1, 6, 0, 3, 6, field_14476, field_14476, false);
				this.fillWithOutline(iWorld, mutableIntBoundingBox, 6, 1, 7, 7, 3, 7, field_14476, field_14476, false);
				this.fillWithOutline(iWorld, mutableIntBoundingBox, 7, 1, 6, 7, 3, 6, field_14476, field_14476, false);
				this.fillWithOutline(iWorld, mutableIntBoundingBox, 6, 1, 0, 7, 3, 0, field_14476, field_14476, false);
				this.fillWithOutline(iWorld, mutableIntBoundingBox, 7, 1, 1, 7, 3, 1, field_14476, field_14476, false);
				this.addBlock(iWorld, field_14473, 1, 2, 0, mutableIntBoundingBox);
				this.addBlock(iWorld, field_14473, 0, 2, 1, mutableIntBoundingBox);
				this.addBlock(iWorld, field_14473, 1, 2, 7, mutableIntBoundingBox);
				this.addBlock(iWorld, field_14473, 0, 2, 6, mutableIntBoundingBox);
				this.addBlock(iWorld, field_14473, 6, 2, 7, mutableIntBoundingBox);
				this.addBlock(iWorld, field_14473, 7, 2, 6, mutableIntBoundingBox);
				this.addBlock(iWorld, field_14473, 6, 2, 0, mutableIntBoundingBox);
				this.addBlock(iWorld, field_14473, 7, 2, 1, mutableIntBoundingBox);
				if (!this.field_14479.field_14482[Direction.SOUTH.getId()]) {
					this.fillWithOutline(iWorld, mutableIntBoundingBox, 1, 3, 0, 6, 3, 0, field_14476, field_14476, false);
					this.fillWithOutline(iWorld, mutableIntBoundingBox, 1, 2, 0, 6, 2, 0, field_14473, field_14473, false);
					this.fillWithOutline(iWorld, mutableIntBoundingBox, 1, 1, 0, 6, 1, 0, field_14476, field_14476, false);
				}

				if (!this.field_14479.field_14482[Direction.NORTH.getId()]) {
					this.fillWithOutline(iWorld, mutableIntBoundingBox, 1, 3, 7, 6, 3, 7, field_14476, field_14476, false);
					this.fillWithOutline(iWorld, mutableIntBoundingBox, 1, 2, 7, 6, 2, 7, field_14473, field_14473, false);
					this.fillWithOutline(iWorld, mutableIntBoundingBox, 1, 1, 7, 6, 1, 7, field_14476, field_14476, false);
				}

				if (!this.field_14479.field_14482[Direction.WEST.getId()]) {
					this.fillWithOutline(iWorld, mutableIntBoundingBox, 0, 3, 1, 0, 3, 6, field_14476, field_14476, false);
					this.fillWithOutline(iWorld, mutableIntBoundingBox, 0, 2, 1, 0, 2, 6, field_14473, field_14473, false);
					this.fillWithOutline(iWorld, mutableIntBoundingBox, 0, 1, 1, 0, 1, 6, field_14476, field_14476, false);
				}

				if (!this.field_14479.field_14482[Direction.EAST.getId()]) {
					this.fillWithOutline(iWorld, mutableIntBoundingBox, 7, 3, 1, 7, 3, 6, field_14476, field_14476, false);
					this.fillWithOutline(iWorld, mutableIntBoundingBox, 7, 2, 1, 7, 2, 6, field_14473, field_14473, false);
					this.fillWithOutline(iWorld, mutableIntBoundingBox, 7, 1, 1, 7, 1, 6, field_14476, field_14476, false);
				}
			} else if (this.field_14480 == 2) {
				this.fillWithOutline(iWorld, mutableIntBoundingBox, 0, 1, 0, 0, 1, 7, field_14476, field_14476, false);
				this.fillWithOutline(iWorld, mutableIntBoundingBox, 7, 1, 0, 7, 1, 7, field_14476, field_14476, false);
				this.fillWithOutline(iWorld, mutableIntBoundingBox, 1, 1, 0, 6, 1, 0, field_14476, field_14476, false);
				this.fillWithOutline(iWorld, mutableIntBoundingBox, 1, 1, 7, 6, 1, 7, field_14476, field_14476, false);
				this.fillWithOutline(iWorld, mutableIntBoundingBox, 0, 2, 0, 0, 2, 7, field_14474, field_14474, false);
				this.fillWithOutline(iWorld, mutableIntBoundingBox, 7, 2, 0, 7, 2, 7, field_14474, field_14474, false);
				this.fillWithOutline(iWorld, mutableIntBoundingBox, 1, 2, 0, 6, 2, 0, field_14474, field_14474, false);
				this.fillWithOutline(iWorld, mutableIntBoundingBox, 1, 2, 7, 6, 2, 7, field_14474, field_14474, false);
				this.fillWithOutline(iWorld, mutableIntBoundingBox, 0, 3, 0, 0, 3, 7, field_14476, field_14476, false);
				this.fillWithOutline(iWorld, mutableIntBoundingBox, 7, 3, 0, 7, 3, 7, field_14476, field_14476, false);
				this.fillWithOutline(iWorld, mutableIntBoundingBox, 1, 3, 0, 6, 3, 0, field_14476, field_14476, false);
				this.fillWithOutline(iWorld, mutableIntBoundingBox, 1, 3, 7, 6, 3, 7, field_14476, field_14476, false);
				this.fillWithOutline(iWorld, mutableIntBoundingBox, 0, 1, 3, 0, 2, 4, field_14474, field_14474, false);
				this.fillWithOutline(iWorld, mutableIntBoundingBox, 7, 1, 3, 7, 2, 4, field_14474, field_14474, false);
				this.fillWithOutline(iWorld, mutableIntBoundingBox, 3, 1, 0, 4, 2, 0, field_14474, field_14474, false);
				this.fillWithOutline(iWorld, mutableIntBoundingBox, 3, 1, 7, 4, 2, 7, field_14474, field_14474, false);
				if (this.field_14479.field_14482[Direction.SOUTH.getId()]) {
					this.method_14773(iWorld, mutableIntBoundingBox, 3, 1, 0, 4, 2, 0);
				}

				if (this.field_14479.field_14482[Direction.NORTH.getId()]) {
					this.method_14773(iWorld, mutableIntBoundingBox, 3, 1, 7, 4, 2, 7);
				}

				if (this.field_14479.field_14482[Direction.WEST.getId()]) {
					this.method_14773(iWorld, mutableIntBoundingBox, 0, 1, 3, 0, 2, 4);
				}

				if (this.field_14479.field_14482[Direction.EAST.getId()]) {
					this.method_14773(iWorld, mutableIntBoundingBox, 7, 1, 3, 7, 2, 4);
				}
			}

			if (bl) {
				this.fillWithOutline(iWorld, mutableIntBoundingBox, 3, 1, 3, 4, 1, 4, field_14476, field_14476, false);
				this.fillWithOutline(iWorld, mutableIntBoundingBox, 3, 2, 3, 4, 2, 4, field_14473, field_14473, false);
				this.fillWithOutline(iWorld, mutableIntBoundingBox, 3, 3, 3, 4, 3, 4, field_14476, field_14476, false);
			}

			return true;
		}
	}

	public static class SimpleRoomTop extends OceanMonumentGenerator.class_3384 {
		public SimpleRoomTop(Direction direction, OceanMonumentGenerator.class_3388 arg) {
			super(StructurePieceType.OCEAN_MONUMENT_SIMPLE_ROOM_TOP, 1, direction, arg, 1, 1, 1);
		}

		public SimpleRoomTop(StructureManager structureManager, CompoundTag compoundTag) {
			super(StructurePieceType.OCEAN_MONUMENT_SIMPLE_ROOM_TOP, compoundTag);
		}

		@Override
		public boolean generate(IWorld iWorld, Random random, MutableIntBoundingBox mutableIntBoundingBox, ChunkPos chunkPos) {
			if (this.field_14479.field_14486 / 25 > 0) {
				this.method_14774(iWorld, mutableIntBoundingBox, 0, 0, this.field_14479.field_14482[Direction.DOWN.getId()]);
			}

			if (this.field_14479.field_14487[Direction.UP.getId()] == null) {
				this.method_14771(iWorld, mutableIntBoundingBox, 1, 4, 1, 6, 4, 6, field_14473);
			}

			for (int i = 1; i <= 6; i++) {
				for (int j = 1; j <= 6; j++) {
					if (random.nextInt(3) != 0) {
						int k = 2 + (random.nextInt(4) == 0 ? 0 : 1);
						BlockState blockState = Blocks.field_10562.getDefaultState();
						this.fillWithOutline(iWorld, mutableIntBoundingBox, i, k, j, i, 3, j, blockState, blockState, false);
					}
				}
			}

			this.fillWithOutline(iWorld, mutableIntBoundingBox, 0, 1, 0, 0, 1, 7, field_14476, field_14476, false);
			this.fillWithOutline(iWorld, mutableIntBoundingBox, 7, 1, 0, 7, 1, 7, field_14476, field_14476, false);
			this.fillWithOutline(iWorld, mutableIntBoundingBox, 1, 1, 0, 6, 1, 0, field_14476, field_14476, false);
			this.fillWithOutline(iWorld, mutableIntBoundingBox, 1, 1, 7, 6, 1, 7, field_14476, field_14476, false);
			this.fillWithOutline(iWorld, mutableIntBoundingBox, 0, 2, 0, 0, 2, 7, field_14474, field_14474, false);
			this.fillWithOutline(iWorld, mutableIntBoundingBox, 7, 2, 0, 7, 2, 7, field_14474, field_14474, false);
			this.fillWithOutline(iWorld, mutableIntBoundingBox, 1, 2, 0, 6, 2, 0, field_14474, field_14474, false);
			this.fillWithOutline(iWorld, mutableIntBoundingBox, 1, 2, 7, 6, 2, 7, field_14474, field_14474, false);
			this.fillWithOutline(iWorld, mutableIntBoundingBox, 0, 3, 0, 0, 3, 7, field_14476, field_14476, false);
			this.fillWithOutline(iWorld, mutableIntBoundingBox, 7, 3, 0, 7, 3, 7, field_14476, field_14476, false);
			this.fillWithOutline(iWorld, mutableIntBoundingBox, 1, 3, 0, 6, 3, 0, field_14476, field_14476, false);
			this.fillWithOutline(iWorld, mutableIntBoundingBox, 1, 3, 7, 6, 3, 7, field_14476, field_14476, false);
			this.fillWithOutline(iWorld, mutableIntBoundingBox, 0, 1, 3, 0, 2, 4, field_14474, field_14474, false);
			this.fillWithOutline(iWorld, mutableIntBoundingBox, 7, 1, 3, 7, 2, 4, field_14474, field_14474, false);
			this.fillWithOutline(iWorld, mutableIntBoundingBox, 3, 1, 0, 4, 2, 0, field_14474, field_14474, false);
			this.fillWithOutline(iWorld, mutableIntBoundingBox, 3, 1, 7, 4, 2, 7, field_14474, field_14474, false);
			if (this.field_14479.field_14482[Direction.SOUTH.getId()]) {
				this.method_14773(iWorld, mutableIntBoundingBox, 3, 1, 0, 4, 2, 0);
			}

			return true;
		}
	}

	static class class_3367 implements OceanMonumentGenerator.class_3375 {
		private class_3367() {
		}

		@Override
		public boolean method_14769(OceanMonumentGenerator.class_3388 arg) {
			return arg.field_14482[Direction.EAST.getId()] && !arg.field_14487[Direction.EAST.getId()].field_14485;
		}

		@Override
		public OceanMonumentGenerator.class_3384 method_14768(Direction direction, OceanMonumentGenerator.class_3388 arg, Random random) {
			arg.field_14485 = true;
			arg.field_14487[Direction.EAST.getId()].field_14485 = true;
			return new OceanMonumentGenerator.class_3377(direction, arg);
		}
	}

	static class class_3368 implements OceanMonumentGenerator.class_3375 {
		private class_3368() {
		}

		@Override
		public boolean method_14769(OceanMonumentGenerator.class_3388 arg) {
			if (arg.field_14482[Direction.EAST.getId()]
				&& !arg.field_14487[Direction.EAST.getId()].field_14485
				&& arg.field_14482[Direction.UP.getId()]
				&& !arg.field_14487[Direction.UP.getId()].field_14485) {
				OceanMonumentGenerator.class_3388 lv = arg.field_14487[Direction.EAST.getId()];
				return lv.field_14482[Direction.UP.getId()] && !lv.field_14487[Direction.UP.getId()].field_14485;
			} else {
				return false;
			}
		}

		@Override
		public OceanMonumentGenerator.class_3384 method_14768(Direction direction, OceanMonumentGenerator.class_3388 arg, Random random) {
			arg.field_14485 = true;
			arg.field_14487[Direction.EAST.getId()].field_14485 = true;
			arg.field_14487[Direction.UP.getId()].field_14485 = true;
			arg.field_14487[Direction.EAST.getId()].field_14487[Direction.UP.getId()].field_14485 = true;
			return new OceanMonumentGenerator.class_3378(direction, arg);
		}
	}

	static class class_3369 implements OceanMonumentGenerator.class_3375 {
		private class_3369() {
		}

		@Override
		public boolean method_14769(OceanMonumentGenerator.class_3388 arg) {
			return arg.field_14482[Direction.UP.getId()] && !arg.field_14487[Direction.UP.getId()].field_14485;
		}

		@Override
		public OceanMonumentGenerator.class_3384 method_14768(Direction direction, OceanMonumentGenerator.class_3388 arg, Random random) {
			arg.field_14485 = true;
			arg.field_14487[Direction.UP.getId()].field_14485 = true;
			return new OceanMonumentGenerator.class_3379(direction, arg);
		}
	}

	static class class_3370 implements OceanMonumentGenerator.class_3375 {
		private class_3370() {
		}

		@Override
		public boolean method_14769(OceanMonumentGenerator.class_3388 arg) {
			if (arg.field_14482[Direction.NORTH.getId()]
				&& !arg.field_14487[Direction.NORTH.getId()].field_14485
				&& arg.field_14482[Direction.UP.getId()]
				&& !arg.field_14487[Direction.UP.getId()].field_14485) {
				OceanMonumentGenerator.class_3388 lv = arg.field_14487[Direction.NORTH.getId()];
				return lv.field_14482[Direction.UP.getId()] && !lv.field_14487[Direction.UP.getId()].field_14485;
			} else {
				return false;
			}
		}

		@Override
		public OceanMonumentGenerator.class_3384 method_14768(Direction direction, OceanMonumentGenerator.class_3388 arg, Random random) {
			arg.field_14485 = true;
			arg.field_14487[Direction.NORTH.getId()].field_14485 = true;
			arg.field_14487[Direction.UP.getId()].field_14485 = true;
			arg.field_14487[Direction.NORTH.getId()].field_14487[Direction.UP.getId()].field_14485 = true;
			return new OceanMonumentGenerator.class_3380(direction, arg);
		}
	}

	static class class_3371 implements OceanMonumentGenerator.class_3375 {
		private class_3371() {
		}

		@Override
		public boolean method_14769(OceanMonumentGenerator.class_3388 arg) {
			return arg.field_14482[Direction.NORTH.getId()] && !arg.field_14487[Direction.NORTH.getId()].field_14485;
		}

		@Override
		public OceanMonumentGenerator.class_3384 method_14768(Direction direction, OceanMonumentGenerator.class_3388 arg, Random random) {
			OceanMonumentGenerator.class_3388 lv = arg;
			if (!arg.field_14482[Direction.NORTH.getId()] || arg.field_14487[Direction.NORTH.getId()].field_14485) {
				lv = arg.field_14487[Direction.SOUTH.getId()];
			}

			lv.field_14485 = true;
			lv.field_14487[Direction.NORTH.getId()].field_14485 = true;
			return new OceanMonumentGenerator.class_3381(direction, lv);
		}
	}

	static class class_3372 implements OceanMonumentGenerator.class_3375 {
		private class_3372() {
		}

		@Override
		public boolean method_14769(OceanMonumentGenerator.class_3388 arg) {
			return true;
		}

		@Override
		public OceanMonumentGenerator.class_3384 method_14768(Direction direction, OceanMonumentGenerator.class_3388 arg, Random random) {
			arg.field_14485 = true;
			return new OceanMonumentGenerator.SimpleRoom(direction, arg, random);
		}
	}

	static class class_3373 implements OceanMonumentGenerator.class_3375 {
		private class_3373() {
		}

		@Override
		public boolean method_14769(OceanMonumentGenerator.class_3388 arg) {
			return !arg.field_14482[Direction.WEST.getId()]
				&& !arg.field_14482[Direction.EAST.getId()]
				&& !arg.field_14482[Direction.NORTH.getId()]
				&& !arg.field_14482[Direction.SOUTH.getId()]
				&& !arg.field_14482[Direction.UP.getId()];
		}

		@Override
		public OceanMonumentGenerator.class_3384 method_14768(Direction direction, OceanMonumentGenerator.class_3388 arg, Random random) {
			arg.field_14485 = true;
			return new OceanMonumentGenerator.SimpleRoomTop(direction, arg);
		}
	}

	public static class class_3374 extends OceanMonumentGenerator.class_3384 {
		private OceanMonumentGenerator.class_3388 field_14464;
		private OceanMonumentGenerator.class_3388 field_14466;
		private final List<OceanMonumentGenerator.class_3384> field_14465 = Lists.<OceanMonumentGenerator.class_3384>newArrayList();

		public class_3374(Random random, int i, int j, Direction direction) {
			super(StructurePieceType.field_16922, 0);
			this.setOrientation(direction);
			Direction direction2 = this.getFacing();
			if (direction2.getAxis() == Direction.Axis.Z) {
				this.boundingBox = new MutableIntBoundingBox(i, 39, j, i + 58 - 1, 61, j + 58 - 1);
			} else {
				this.boundingBox = new MutableIntBoundingBox(i, 39, j, i + 58 - 1, 61, j + 58 - 1);
			}

			List<OceanMonumentGenerator.class_3388> list = this.method_14760(random);
			this.field_14464.field_14485 = true;
			this.field_14465.add(new OceanMonumentGenerator.Entry(direction2, this.field_14464));
			this.field_14465.add(new OceanMonumentGenerator.class_3376(direction2, this.field_14466));
			List<OceanMonumentGenerator.class_3375> list2 = Lists.<OceanMonumentGenerator.class_3375>newArrayList();
			list2.add(new OceanMonumentGenerator.class_3368());
			list2.add(new OceanMonumentGenerator.class_3370());
			list2.add(new OceanMonumentGenerator.class_3371());
			list2.add(new OceanMonumentGenerator.class_3367());
			list2.add(new OceanMonumentGenerator.class_3369());
			list2.add(new OceanMonumentGenerator.class_3373());
			list2.add(new OceanMonumentGenerator.class_3372());

			for (OceanMonumentGenerator.class_3388 lv : list) {
				if (!lv.field_14485 && !lv.method_14785()) {
					for (OceanMonumentGenerator.class_3375 lv2 : list2) {
						if (lv2.method_14769(lv)) {
							this.field_14465.add(lv2.method_14768(direction2, lv, random));
							break;
						}
					}
				}
			}

			int k = this.boundingBox.minY;
			int l = this.applyXTransform(9, 22);
			int m = this.applyZTransform(9, 22);

			for (OceanMonumentGenerator.class_3384 lv3 : this.field_14465) {
				lv3.getBoundingBox().translate(l, k, m);
			}

			MutableIntBoundingBox mutableIntBoundingBox = MutableIntBoundingBox.create(
				this.applyXTransform(1, 1),
				this.applyYTransform(1),
				this.applyZTransform(1, 1),
				this.applyXTransform(23, 21),
				this.applyYTransform(8),
				this.applyZTransform(23, 21)
			);
			MutableIntBoundingBox mutableIntBoundingBox2 = MutableIntBoundingBox.create(
				this.applyXTransform(34, 1),
				this.applyYTransform(1),
				this.applyZTransform(34, 1),
				this.applyXTransform(56, 21),
				this.applyYTransform(8),
				this.applyZTransform(56, 21)
			);
			MutableIntBoundingBox mutableIntBoundingBox3 = MutableIntBoundingBox.create(
				this.applyXTransform(22, 22),
				this.applyYTransform(13),
				this.applyZTransform(22, 22),
				this.applyXTransform(35, 35),
				this.applyYTransform(17),
				this.applyZTransform(35, 35)
			);
			int n = random.nextInt();
			this.field_14465.add(new OceanMonumentGenerator.class_3387(direction2, mutableIntBoundingBox, n++));
			this.field_14465.add(new OceanMonumentGenerator.class_3387(direction2, mutableIntBoundingBox2, n++));
			this.field_14465.add(new OceanMonumentGenerator.Penthouse(direction2, mutableIntBoundingBox3));
		}

		public class_3374(StructureManager structureManager, CompoundTag compoundTag) {
			super(StructurePieceType.field_16922, compoundTag);
		}

		private List<OceanMonumentGenerator.class_3388> method_14760(Random random) {
			OceanMonumentGenerator.class_3388[] lvs = new OceanMonumentGenerator.class_3388[75];

			for (int i = 0; i < 5; i++) {
				for (int j = 0; j < 4; j++) {
					int k = 0;
					int l = method_14770(i, 0, j);
					lvs[l] = new OceanMonumentGenerator.class_3388(l);
				}
			}

			for (int i = 0; i < 5; i++) {
				for (int j = 0; j < 4; j++) {
					int k = 1;
					int l = method_14770(i, 1, j);
					lvs[l] = new OceanMonumentGenerator.class_3388(l);
				}
			}

			for (int i = 1; i < 4; i++) {
				for (int j = 0; j < 2; j++) {
					int k = 2;
					int l = method_14770(i, 2, j);
					lvs[l] = new OceanMonumentGenerator.class_3388(l);
				}
			}

			this.field_14464 = lvs[field_14469];

			for (int i = 0; i < 5; i++) {
				for (int j = 0; j < 5; j++) {
					for (int k = 0; k < 3; k++) {
						int l = method_14770(i, k, j);
						if (lvs[l] != null) {
							for (Direction direction : Direction.values()) {
								int m = i + direction.getOffsetX();
								int n = k + direction.getOffsetY();
								int o = j + direction.getOffsetZ();
								if (m >= 0 && m < 5 && o >= 0 && o < 5 && n >= 0 && n < 3) {
									int p = method_14770(m, n, o);
									if (lvs[p] != null) {
										if (o == j) {
											lvs[l].method_14786(direction, lvs[p]);
										} else {
											lvs[l].method_14786(direction.getOpposite(), lvs[p]);
										}
									}
								}
							}
						}
					}
				}
			}

			OceanMonumentGenerator.class_3388 lv = new OceanMonumentGenerator.class_3388(1003);
			OceanMonumentGenerator.class_3388 lv2 = new OceanMonumentGenerator.class_3388(1001);
			OceanMonumentGenerator.class_3388 lv3 = new OceanMonumentGenerator.class_3388(1002);
			lvs[field_14468].method_14786(Direction.UP, lv);
			lvs[field_14478].method_14786(Direction.SOUTH, lv2);
			lvs[field_14477].method_14786(Direction.SOUTH, lv3);
			lv.field_14485 = true;
			lv2.field_14485 = true;
			lv3.field_14485 = true;
			this.field_14464.field_14484 = true;
			this.field_14466 = lvs[method_14770(random.nextInt(4), 0, 2)];
			this.field_14466.field_14485 = true;
			this.field_14466.field_14487[Direction.EAST.getId()].field_14485 = true;
			this.field_14466.field_14487[Direction.NORTH.getId()].field_14485 = true;
			this.field_14466.field_14487[Direction.EAST.getId()].field_14487[Direction.NORTH.getId()].field_14485 = true;
			this.field_14466.field_14487[Direction.UP.getId()].field_14485 = true;
			this.field_14466.field_14487[Direction.EAST.getId()].field_14487[Direction.UP.getId()].field_14485 = true;
			this.field_14466.field_14487[Direction.NORTH.getId()].field_14487[Direction.UP.getId()].field_14485 = true;
			this.field_14466.field_14487[Direction.EAST.getId()].field_14487[Direction.NORTH.getId()].field_14487[Direction.UP.getId()].field_14485 = true;
			List<OceanMonumentGenerator.class_3388> list = Lists.<OceanMonumentGenerator.class_3388>newArrayList();

			for (OceanMonumentGenerator.class_3388 lv4 : lvs) {
				if (lv4 != null) {
					lv4.method_14780();
					list.add(lv4);
				}
			}

			lv.method_14780();
			Collections.shuffle(list, random);
			int q = 1;

			for (OceanMonumentGenerator.class_3388 lv5 : list) {
				int r = 0;
				int m = 0;

				while (r < 2 && m < 5) {
					m++;
					int n = random.nextInt(6);
					if (lv5.field_14482[n]) {
						int o = Direction.byId(n).getOpposite().getId();
						lv5.field_14482[n] = false;
						lv5.field_14487[n].field_14482[o] = false;
						if (lv5.method_14783(q++) && lv5.field_14487[n].method_14783(q++)) {
							r++;
						} else {
							lv5.field_14482[n] = true;
							lv5.field_14487[n].field_14482[o] = true;
						}
					}
				}
			}

			list.add(lv);
			list.add(lv2);
			list.add(lv3);
			return list;
		}

		@Override
		public boolean generate(IWorld iWorld, Random random, MutableIntBoundingBox mutableIntBoundingBox, ChunkPos chunkPos) {
			int i = Math.max(iWorld.getSeaLevel(), 64) - this.boundingBox.minY;
			this.method_14773(iWorld, mutableIntBoundingBox, 0, 0, 0, 58, i, 58);
			this.method_14761(false, 0, iWorld, random, mutableIntBoundingBox);
			this.method_14761(true, 33, iWorld, random, mutableIntBoundingBox);
			this.method_14763(iWorld, random, mutableIntBoundingBox);
			this.method_14762(iWorld, random, mutableIntBoundingBox);
			this.method_14765(iWorld, random, mutableIntBoundingBox);
			this.method_14764(iWorld, random, mutableIntBoundingBox);
			this.method_14766(iWorld, random, mutableIntBoundingBox);
			this.method_14767(iWorld, random, mutableIntBoundingBox);

			for (int j = 0; j < 7; j++) {
				int k = 0;

				while (k < 7) {
					if (k == 0 && j == 3) {
						k = 6;
					}

					int l = j * 9;
					int m = k * 9;

					for (int n = 0; n < 4; n++) {
						for (int o = 0; o < 4; o++) {
							this.addBlock(iWorld, field_14476, l + n, 0, m + o, mutableIntBoundingBox);
							this.method_14936(iWorld, field_14476, l + n, -1, m + o, mutableIntBoundingBox);
						}
					}

					if (j != 0 && j != 6) {
						k += 6;
					} else {
						k++;
					}
				}
			}

			for (int j = 0; j < 5; j++) {
				this.method_14773(iWorld, mutableIntBoundingBox, -1 - j, 0 + j * 2, -1 - j, -1 - j, 23, 58 + j);
				this.method_14773(iWorld, mutableIntBoundingBox, 58 + j, 0 + j * 2, -1 - j, 58 + j, 23, 58 + j);
				this.method_14773(iWorld, mutableIntBoundingBox, 0 - j, 0 + j * 2, -1 - j, 57 + j, 23, -1 - j);
				this.method_14773(iWorld, mutableIntBoundingBox, 0 - j, 0 + j * 2, 58 + j, 57 + j, 23, 58 + j);
			}

			for (OceanMonumentGenerator.class_3384 lv : this.field_14465) {
				if (lv.getBoundingBox().intersects(mutableIntBoundingBox)) {
					lv.generate(iWorld, random, mutableIntBoundingBox, chunkPos);
				}
			}

			return true;
		}

		private void method_14761(boolean bl, int i, IWorld iWorld, Random random, MutableIntBoundingBox mutableIntBoundingBox) {
			int j = 24;
			if (this.method_14775(mutableIntBoundingBox, i, 0, i + 23, 20)) {
				this.fillWithOutline(iWorld, mutableIntBoundingBox, i + 0, 0, 0, i + 24, 0, 20, field_14473, field_14473, false);
				this.method_14773(iWorld, mutableIntBoundingBox, i + 0, 1, 0, i + 24, 10, 20);

				for (int k = 0; k < 4; k++) {
					this.fillWithOutline(iWorld, mutableIntBoundingBox, i + k, k + 1, k, i + k, k + 1, 20, field_14476, field_14476, false);
					this.fillWithOutline(iWorld, mutableIntBoundingBox, i + k + 7, k + 5, k + 7, i + k + 7, k + 5, 20, field_14476, field_14476, false);
					this.fillWithOutline(iWorld, mutableIntBoundingBox, i + 17 - k, k + 5, k + 7, i + 17 - k, k + 5, 20, field_14476, field_14476, false);
					this.fillWithOutline(iWorld, mutableIntBoundingBox, i + 24 - k, k + 1, k, i + 24 - k, k + 1, 20, field_14476, field_14476, false);
					this.fillWithOutline(iWorld, mutableIntBoundingBox, i + k + 1, k + 1, k, i + 23 - k, k + 1, k, field_14476, field_14476, false);
					this.fillWithOutline(iWorld, mutableIntBoundingBox, i + k + 8, k + 5, k + 7, i + 16 - k, k + 5, k + 7, field_14476, field_14476, false);
				}

				this.fillWithOutline(iWorld, mutableIntBoundingBox, i + 4, 4, 4, i + 6, 4, 20, field_14473, field_14473, false);
				this.fillWithOutline(iWorld, mutableIntBoundingBox, i + 7, 4, 4, i + 17, 4, 6, field_14473, field_14473, false);
				this.fillWithOutline(iWorld, mutableIntBoundingBox, i + 18, 4, 4, i + 20, 4, 20, field_14473, field_14473, false);
				this.fillWithOutline(iWorld, mutableIntBoundingBox, i + 11, 8, 11, i + 13, 8, 20, field_14473, field_14473, false);
				this.addBlock(iWorld, field_14470, i + 12, 9, 12, mutableIntBoundingBox);
				this.addBlock(iWorld, field_14470, i + 12, 9, 15, mutableIntBoundingBox);
				this.addBlock(iWorld, field_14470, i + 12, 9, 18, mutableIntBoundingBox);
				int k = i + (bl ? 19 : 5);
				int l = i + (bl ? 5 : 19);

				for (int m = 20; m >= 5; m -= 3) {
					this.addBlock(iWorld, field_14470, k, 5, m, mutableIntBoundingBox);
				}

				for (int m = 19; m >= 7; m -= 3) {
					this.addBlock(iWorld, field_14470, l, 5, m, mutableIntBoundingBox);
				}

				for (int m = 0; m < 4; m++) {
					int n = bl ? i + 24 - (17 - m * 3) : i + 17 - m * 3;
					this.addBlock(iWorld, field_14470, n, 5, 5, mutableIntBoundingBox);
				}

				this.addBlock(iWorld, field_14470, l, 5, 5, mutableIntBoundingBox);
				this.fillWithOutline(iWorld, mutableIntBoundingBox, i + 11, 1, 12, i + 13, 7, 12, field_14473, field_14473, false);
				this.fillWithOutline(iWorld, mutableIntBoundingBox, i + 12, 1, 11, i + 12, 7, 13, field_14473, field_14473, false);
			}
		}

		private void method_14763(IWorld iWorld, Random random, MutableIntBoundingBox mutableIntBoundingBox) {
			if (this.method_14775(mutableIntBoundingBox, 22, 5, 35, 17)) {
				this.method_14773(iWorld, mutableIntBoundingBox, 25, 0, 0, 32, 8, 20);

				for (int i = 0; i < 4; i++) {
					this.fillWithOutline(iWorld, mutableIntBoundingBox, 24, 2, 5 + i * 4, 24, 4, 5 + i * 4, field_14476, field_14476, false);
					this.fillWithOutline(iWorld, mutableIntBoundingBox, 22, 4, 5 + i * 4, 23, 4, 5 + i * 4, field_14476, field_14476, false);
					this.addBlock(iWorld, field_14476, 25, 5, 5 + i * 4, mutableIntBoundingBox);
					this.addBlock(iWorld, field_14476, 26, 6, 5 + i * 4, mutableIntBoundingBox);
					this.addBlock(iWorld, field_14471, 26, 5, 5 + i * 4, mutableIntBoundingBox);
					this.fillWithOutline(iWorld, mutableIntBoundingBox, 33, 2, 5 + i * 4, 33, 4, 5 + i * 4, field_14476, field_14476, false);
					this.fillWithOutline(iWorld, mutableIntBoundingBox, 34, 4, 5 + i * 4, 35, 4, 5 + i * 4, field_14476, field_14476, false);
					this.addBlock(iWorld, field_14476, 32, 5, 5 + i * 4, mutableIntBoundingBox);
					this.addBlock(iWorld, field_14476, 31, 6, 5 + i * 4, mutableIntBoundingBox);
					this.addBlock(iWorld, field_14471, 31, 5, 5 + i * 4, mutableIntBoundingBox);
					this.fillWithOutline(iWorld, mutableIntBoundingBox, 27, 6, 5 + i * 4, 30, 6, 5 + i * 4, field_14473, field_14473, false);
				}
			}
		}

		private void method_14762(IWorld iWorld, Random random, MutableIntBoundingBox mutableIntBoundingBox) {
			if (this.method_14775(mutableIntBoundingBox, 15, 20, 42, 21)) {
				this.fillWithOutline(iWorld, mutableIntBoundingBox, 15, 0, 21, 42, 0, 21, field_14473, field_14473, false);
				this.method_14773(iWorld, mutableIntBoundingBox, 26, 1, 21, 31, 3, 21);
				this.fillWithOutline(iWorld, mutableIntBoundingBox, 21, 12, 21, 36, 12, 21, field_14473, field_14473, false);
				this.fillWithOutline(iWorld, mutableIntBoundingBox, 17, 11, 21, 40, 11, 21, field_14473, field_14473, false);
				this.fillWithOutline(iWorld, mutableIntBoundingBox, 16, 10, 21, 41, 10, 21, field_14473, field_14473, false);
				this.fillWithOutline(iWorld, mutableIntBoundingBox, 15, 7, 21, 42, 9, 21, field_14473, field_14473, false);
				this.fillWithOutline(iWorld, mutableIntBoundingBox, 16, 6, 21, 41, 6, 21, field_14473, field_14473, false);
				this.fillWithOutline(iWorld, mutableIntBoundingBox, 17, 5, 21, 40, 5, 21, field_14473, field_14473, false);
				this.fillWithOutline(iWorld, mutableIntBoundingBox, 21, 4, 21, 36, 4, 21, field_14473, field_14473, false);
				this.fillWithOutline(iWorld, mutableIntBoundingBox, 22, 3, 21, 26, 3, 21, field_14473, field_14473, false);
				this.fillWithOutline(iWorld, mutableIntBoundingBox, 31, 3, 21, 35, 3, 21, field_14473, field_14473, false);
				this.fillWithOutline(iWorld, mutableIntBoundingBox, 23, 2, 21, 25, 2, 21, field_14473, field_14473, false);
				this.fillWithOutline(iWorld, mutableIntBoundingBox, 32, 2, 21, 34, 2, 21, field_14473, field_14473, false);
				this.fillWithOutline(iWorld, mutableIntBoundingBox, 28, 4, 20, 29, 4, 21, field_14476, field_14476, false);
				this.addBlock(iWorld, field_14476, 27, 3, 21, mutableIntBoundingBox);
				this.addBlock(iWorld, field_14476, 30, 3, 21, mutableIntBoundingBox);
				this.addBlock(iWorld, field_14476, 26, 2, 21, mutableIntBoundingBox);
				this.addBlock(iWorld, field_14476, 31, 2, 21, mutableIntBoundingBox);
				this.addBlock(iWorld, field_14476, 25, 1, 21, mutableIntBoundingBox);
				this.addBlock(iWorld, field_14476, 32, 1, 21, mutableIntBoundingBox);

				for (int i = 0; i < 7; i++) {
					this.addBlock(iWorld, field_14474, 28 - i, 6 + i, 21, mutableIntBoundingBox);
					this.addBlock(iWorld, field_14474, 29 + i, 6 + i, 21, mutableIntBoundingBox);
				}

				for (int i = 0; i < 4; i++) {
					this.addBlock(iWorld, field_14474, 28 - i, 9 + i, 21, mutableIntBoundingBox);
					this.addBlock(iWorld, field_14474, 29 + i, 9 + i, 21, mutableIntBoundingBox);
				}

				this.addBlock(iWorld, field_14474, 28, 12, 21, mutableIntBoundingBox);
				this.addBlock(iWorld, field_14474, 29, 12, 21, mutableIntBoundingBox);

				for (int i = 0; i < 3; i++) {
					this.addBlock(iWorld, field_14474, 22 - i * 2, 8, 21, mutableIntBoundingBox);
					this.addBlock(iWorld, field_14474, 22 - i * 2, 9, 21, mutableIntBoundingBox);
					this.addBlock(iWorld, field_14474, 35 + i * 2, 8, 21, mutableIntBoundingBox);
					this.addBlock(iWorld, field_14474, 35 + i * 2, 9, 21, mutableIntBoundingBox);
				}

				this.method_14773(iWorld, mutableIntBoundingBox, 15, 13, 21, 42, 15, 21);
				this.method_14773(iWorld, mutableIntBoundingBox, 15, 1, 21, 15, 6, 21);
				this.method_14773(iWorld, mutableIntBoundingBox, 16, 1, 21, 16, 5, 21);
				this.method_14773(iWorld, mutableIntBoundingBox, 17, 1, 21, 20, 4, 21);
				this.method_14773(iWorld, mutableIntBoundingBox, 21, 1, 21, 21, 3, 21);
				this.method_14773(iWorld, mutableIntBoundingBox, 22, 1, 21, 22, 2, 21);
				this.method_14773(iWorld, mutableIntBoundingBox, 23, 1, 21, 24, 1, 21);
				this.method_14773(iWorld, mutableIntBoundingBox, 42, 1, 21, 42, 6, 21);
				this.method_14773(iWorld, mutableIntBoundingBox, 41, 1, 21, 41, 5, 21);
				this.method_14773(iWorld, mutableIntBoundingBox, 37, 1, 21, 40, 4, 21);
				this.method_14773(iWorld, mutableIntBoundingBox, 36, 1, 21, 36, 3, 21);
				this.method_14773(iWorld, mutableIntBoundingBox, 33, 1, 21, 34, 1, 21);
				this.method_14773(iWorld, mutableIntBoundingBox, 35, 1, 21, 35, 2, 21);
			}
		}

		private void method_14765(IWorld iWorld, Random random, MutableIntBoundingBox mutableIntBoundingBox) {
			if (this.method_14775(mutableIntBoundingBox, 21, 21, 36, 36)) {
				this.fillWithOutline(iWorld, mutableIntBoundingBox, 21, 0, 22, 36, 0, 36, field_14473, field_14473, false);
				this.method_14773(iWorld, mutableIntBoundingBox, 21, 1, 22, 36, 23, 36);

				for (int i = 0; i < 4; i++) {
					this.fillWithOutline(iWorld, mutableIntBoundingBox, 21 + i, 13 + i, 21 + i, 36 - i, 13 + i, 21 + i, field_14476, field_14476, false);
					this.fillWithOutline(iWorld, mutableIntBoundingBox, 21 + i, 13 + i, 36 - i, 36 - i, 13 + i, 36 - i, field_14476, field_14476, false);
					this.fillWithOutline(iWorld, mutableIntBoundingBox, 21 + i, 13 + i, 22 + i, 21 + i, 13 + i, 35 - i, field_14476, field_14476, false);
					this.fillWithOutline(iWorld, mutableIntBoundingBox, 36 - i, 13 + i, 22 + i, 36 - i, 13 + i, 35 - i, field_14476, field_14476, false);
				}

				this.fillWithOutline(iWorld, mutableIntBoundingBox, 25, 16, 25, 32, 16, 32, field_14473, field_14473, false);
				this.fillWithOutline(iWorld, mutableIntBoundingBox, 25, 17, 25, 25, 19, 25, field_14476, field_14476, false);
				this.fillWithOutline(iWorld, mutableIntBoundingBox, 32, 17, 25, 32, 19, 25, field_14476, field_14476, false);
				this.fillWithOutline(iWorld, mutableIntBoundingBox, 25, 17, 32, 25, 19, 32, field_14476, field_14476, false);
				this.fillWithOutline(iWorld, mutableIntBoundingBox, 32, 17, 32, 32, 19, 32, field_14476, field_14476, false);
				this.addBlock(iWorld, field_14476, 26, 20, 26, mutableIntBoundingBox);
				this.addBlock(iWorld, field_14476, 27, 21, 27, mutableIntBoundingBox);
				this.addBlock(iWorld, field_14471, 27, 20, 27, mutableIntBoundingBox);
				this.addBlock(iWorld, field_14476, 26, 20, 31, mutableIntBoundingBox);
				this.addBlock(iWorld, field_14476, 27, 21, 30, mutableIntBoundingBox);
				this.addBlock(iWorld, field_14471, 27, 20, 30, mutableIntBoundingBox);
				this.addBlock(iWorld, field_14476, 31, 20, 31, mutableIntBoundingBox);
				this.addBlock(iWorld, field_14476, 30, 21, 30, mutableIntBoundingBox);
				this.addBlock(iWorld, field_14471, 30, 20, 30, mutableIntBoundingBox);
				this.addBlock(iWorld, field_14476, 31, 20, 26, mutableIntBoundingBox);
				this.addBlock(iWorld, field_14476, 30, 21, 27, mutableIntBoundingBox);
				this.addBlock(iWorld, field_14471, 30, 20, 27, mutableIntBoundingBox);
				this.fillWithOutline(iWorld, mutableIntBoundingBox, 28, 21, 27, 29, 21, 27, field_14473, field_14473, false);
				this.fillWithOutline(iWorld, mutableIntBoundingBox, 27, 21, 28, 27, 21, 29, field_14473, field_14473, false);
				this.fillWithOutline(iWorld, mutableIntBoundingBox, 28, 21, 30, 29, 21, 30, field_14473, field_14473, false);
				this.fillWithOutline(iWorld, mutableIntBoundingBox, 30, 21, 28, 30, 21, 29, field_14473, field_14473, false);
			}
		}

		private void method_14764(IWorld iWorld, Random random, MutableIntBoundingBox mutableIntBoundingBox) {
			if (this.method_14775(mutableIntBoundingBox, 0, 21, 6, 58)) {
				this.fillWithOutline(iWorld, mutableIntBoundingBox, 0, 0, 21, 6, 0, 57, field_14473, field_14473, false);
				this.method_14773(iWorld, mutableIntBoundingBox, 0, 1, 21, 6, 7, 57);
				this.fillWithOutline(iWorld, mutableIntBoundingBox, 4, 4, 21, 6, 4, 53, field_14473, field_14473, false);

				for (int i = 0; i < 4; i++) {
					this.fillWithOutline(iWorld, mutableIntBoundingBox, i, i + 1, 21, i, i + 1, 57 - i, field_14476, field_14476, false);
				}

				for (int i = 23; i < 53; i += 3) {
					this.addBlock(iWorld, field_14470, 5, 5, i, mutableIntBoundingBox);
				}

				this.addBlock(iWorld, field_14470, 5, 5, 52, mutableIntBoundingBox);

				for (int i = 0; i < 4; i++) {
					this.fillWithOutline(iWorld, mutableIntBoundingBox, i, i + 1, 21, i, i + 1, 57 - i, field_14476, field_14476, false);
				}

				this.fillWithOutline(iWorld, mutableIntBoundingBox, 4, 1, 52, 6, 3, 52, field_14473, field_14473, false);
				this.fillWithOutline(iWorld, mutableIntBoundingBox, 5, 1, 51, 5, 3, 53, field_14473, field_14473, false);
			}

			if (this.method_14775(mutableIntBoundingBox, 51, 21, 58, 58)) {
				this.fillWithOutline(iWorld, mutableIntBoundingBox, 51, 0, 21, 57, 0, 57, field_14473, field_14473, false);
				this.method_14773(iWorld, mutableIntBoundingBox, 51, 1, 21, 57, 7, 57);
				this.fillWithOutline(iWorld, mutableIntBoundingBox, 51, 4, 21, 53, 4, 53, field_14473, field_14473, false);

				for (int i = 0; i < 4; i++) {
					this.fillWithOutline(iWorld, mutableIntBoundingBox, 57 - i, i + 1, 21, 57 - i, i + 1, 57 - i, field_14476, field_14476, false);
				}

				for (int i = 23; i < 53; i += 3) {
					this.addBlock(iWorld, field_14470, 52, 5, i, mutableIntBoundingBox);
				}

				this.addBlock(iWorld, field_14470, 52, 5, 52, mutableIntBoundingBox);
				this.fillWithOutline(iWorld, mutableIntBoundingBox, 51, 1, 52, 53, 3, 52, field_14473, field_14473, false);
				this.fillWithOutline(iWorld, mutableIntBoundingBox, 52, 1, 51, 52, 3, 53, field_14473, field_14473, false);
			}

			if (this.method_14775(mutableIntBoundingBox, 0, 51, 57, 57)) {
				this.fillWithOutline(iWorld, mutableIntBoundingBox, 7, 0, 51, 50, 0, 57, field_14473, field_14473, false);
				this.method_14773(iWorld, mutableIntBoundingBox, 7, 1, 51, 50, 10, 57);

				for (int i = 0; i < 4; i++) {
					this.fillWithOutline(iWorld, mutableIntBoundingBox, i + 1, i + 1, 57 - i, 56 - i, i + 1, 57 - i, field_14476, field_14476, false);
				}
			}
		}

		private void method_14766(IWorld iWorld, Random random, MutableIntBoundingBox mutableIntBoundingBox) {
			if (this.method_14775(mutableIntBoundingBox, 7, 21, 13, 50)) {
				this.fillWithOutline(iWorld, mutableIntBoundingBox, 7, 0, 21, 13, 0, 50, field_14473, field_14473, false);
				this.method_14773(iWorld, mutableIntBoundingBox, 7, 1, 21, 13, 10, 50);
				this.fillWithOutline(iWorld, mutableIntBoundingBox, 11, 8, 21, 13, 8, 53, field_14473, field_14473, false);

				for (int i = 0; i < 4; i++) {
					this.fillWithOutline(iWorld, mutableIntBoundingBox, i + 7, i + 5, 21, i + 7, i + 5, 54, field_14476, field_14476, false);
				}

				for (int i = 21; i <= 45; i += 3) {
					this.addBlock(iWorld, field_14470, 12, 9, i, mutableIntBoundingBox);
				}
			}

			if (this.method_14775(mutableIntBoundingBox, 44, 21, 50, 54)) {
				this.fillWithOutline(iWorld, mutableIntBoundingBox, 44, 0, 21, 50, 0, 50, field_14473, field_14473, false);
				this.method_14773(iWorld, mutableIntBoundingBox, 44, 1, 21, 50, 10, 50);
				this.fillWithOutline(iWorld, mutableIntBoundingBox, 44, 8, 21, 46, 8, 53, field_14473, field_14473, false);

				for (int i = 0; i < 4; i++) {
					this.fillWithOutline(iWorld, mutableIntBoundingBox, 50 - i, i + 5, 21, 50 - i, i + 5, 54, field_14476, field_14476, false);
				}

				for (int i = 21; i <= 45; i += 3) {
					this.addBlock(iWorld, field_14470, 45, 9, i, mutableIntBoundingBox);
				}
			}

			if (this.method_14775(mutableIntBoundingBox, 8, 44, 49, 54)) {
				this.fillWithOutline(iWorld, mutableIntBoundingBox, 14, 0, 44, 43, 0, 50, field_14473, field_14473, false);
				this.method_14773(iWorld, mutableIntBoundingBox, 14, 1, 44, 43, 10, 50);

				for (int i = 12; i <= 45; i += 3) {
					this.addBlock(iWorld, field_14470, i, 9, 45, mutableIntBoundingBox);
					this.addBlock(iWorld, field_14470, i, 9, 52, mutableIntBoundingBox);
					if (i == 12 || i == 18 || i == 24 || i == 33 || i == 39 || i == 45) {
						this.addBlock(iWorld, field_14470, i, 9, 47, mutableIntBoundingBox);
						this.addBlock(iWorld, field_14470, i, 9, 50, mutableIntBoundingBox);
						this.addBlock(iWorld, field_14470, i, 10, 45, mutableIntBoundingBox);
						this.addBlock(iWorld, field_14470, i, 10, 46, mutableIntBoundingBox);
						this.addBlock(iWorld, field_14470, i, 10, 51, mutableIntBoundingBox);
						this.addBlock(iWorld, field_14470, i, 10, 52, mutableIntBoundingBox);
						this.addBlock(iWorld, field_14470, i, 11, 47, mutableIntBoundingBox);
						this.addBlock(iWorld, field_14470, i, 11, 50, mutableIntBoundingBox);
						this.addBlock(iWorld, field_14470, i, 12, 48, mutableIntBoundingBox);
						this.addBlock(iWorld, field_14470, i, 12, 49, mutableIntBoundingBox);
					}
				}

				for (int ix = 0; ix < 3; ix++) {
					this.fillWithOutline(iWorld, mutableIntBoundingBox, 8 + ix, 5 + ix, 54, 49 - ix, 5 + ix, 54, field_14473, field_14473, false);
				}

				this.fillWithOutline(iWorld, mutableIntBoundingBox, 11, 8, 54, 46, 8, 54, field_14476, field_14476, false);
				this.fillWithOutline(iWorld, mutableIntBoundingBox, 14, 8, 44, 43, 8, 53, field_14473, field_14473, false);
			}
		}

		private void method_14767(IWorld iWorld, Random random, MutableIntBoundingBox mutableIntBoundingBox) {
			if (this.method_14775(mutableIntBoundingBox, 14, 21, 20, 43)) {
				this.fillWithOutline(iWorld, mutableIntBoundingBox, 14, 0, 21, 20, 0, 43, field_14473, field_14473, false);
				this.method_14773(iWorld, mutableIntBoundingBox, 14, 1, 22, 20, 14, 43);
				this.fillWithOutline(iWorld, mutableIntBoundingBox, 18, 12, 22, 20, 12, 39, field_14473, field_14473, false);
				this.fillWithOutline(iWorld, mutableIntBoundingBox, 18, 12, 21, 20, 12, 21, field_14476, field_14476, false);

				for (int i = 0; i < 4; i++) {
					this.fillWithOutline(iWorld, mutableIntBoundingBox, i + 14, i + 9, 21, i + 14, i + 9, 43 - i, field_14476, field_14476, false);
				}

				for (int i = 23; i <= 39; i += 3) {
					this.addBlock(iWorld, field_14470, 19, 13, i, mutableIntBoundingBox);
				}
			}

			if (this.method_14775(mutableIntBoundingBox, 37, 21, 43, 43)) {
				this.fillWithOutline(iWorld, mutableIntBoundingBox, 37, 0, 21, 43, 0, 43, field_14473, field_14473, false);
				this.method_14773(iWorld, mutableIntBoundingBox, 37, 1, 22, 43, 14, 43);
				this.fillWithOutline(iWorld, mutableIntBoundingBox, 37, 12, 22, 39, 12, 39, field_14473, field_14473, false);
				this.fillWithOutline(iWorld, mutableIntBoundingBox, 37, 12, 21, 39, 12, 21, field_14476, field_14476, false);

				for (int i = 0; i < 4; i++) {
					this.fillWithOutline(iWorld, mutableIntBoundingBox, 43 - i, i + 9, 21, 43 - i, i + 9, 43 - i, field_14476, field_14476, false);
				}

				for (int i = 23; i <= 39; i += 3) {
					this.addBlock(iWorld, field_14470, 38, 13, i, mutableIntBoundingBox);
				}
			}

			if (this.method_14775(mutableIntBoundingBox, 15, 37, 42, 43)) {
				this.fillWithOutline(iWorld, mutableIntBoundingBox, 21, 0, 37, 36, 0, 43, field_14473, field_14473, false);
				this.method_14773(iWorld, mutableIntBoundingBox, 21, 1, 37, 36, 14, 43);
				this.fillWithOutline(iWorld, mutableIntBoundingBox, 21, 12, 37, 36, 12, 39, field_14473, field_14473, false);

				for (int i = 0; i < 4; i++) {
					this.fillWithOutline(iWorld, mutableIntBoundingBox, 15 + i, i + 9, 43 - i, 42 - i, i + 9, 43 - i, field_14476, field_14476, false);
				}

				for (int i = 21; i <= 36; i += 3) {
					this.addBlock(iWorld, field_14470, i, 13, 38, mutableIntBoundingBox);
				}
			}
		}
	}

	interface class_3375 {
		boolean method_14769(OceanMonumentGenerator.class_3388 arg);

		OceanMonumentGenerator.class_3384 method_14768(Direction direction, OceanMonumentGenerator.class_3388 arg, Random random);
	}

	public static class class_3376 extends OceanMonumentGenerator.class_3384 {
		public class_3376(Direction direction, OceanMonumentGenerator.class_3388 arg) {
			super(StructurePieceType.field_16911, 1, direction, arg, 2, 2, 2);
		}

		public class_3376(StructureManager structureManager, CompoundTag compoundTag) {
			super(StructurePieceType.field_16911, compoundTag);
		}

		@Override
		public boolean generate(IWorld iWorld, Random random, MutableIntBoundingBox mutableIntBoundingBox, ChunkPos chunkPos) {
			this.method_14771(iWorld, mutableIntBoundingBox, 1, 8, 0, 14, 8, 14, field_14473);
			int i = 7;
			BlockState blockState = field_14476;
			this.fillWithOutline(iWorld, mutableIntBoundingBox, 0, 7, 0, 0, 7, 15, blockState, blockState, false);
			this.fillWithOutline(iWorld, mutableIntBoundingBox, 15, 7, 0, 15, 7, 15, blockState, blockState, false);
			this.fillWithOutline(iWorld, mutableIntBoundingBox, 1, 7, 0, 15, 7, 0, blockState, blockState, false);
			this.fillWithOutline(iWorld, mutableIntBoundingBox, 1, 7, 15, 14, 7, 15, blockState, blockState, false);

			for (int ix = 1; ix <= 6; ix++) {
				blockState = field_14476;
				if (ix == 2 || ix == 6) {
					blockState = field_14473;
				}

				for (int j = 0; j <= 15; j += 15) {
					this.fillWithOutline(iWorld, mutableIntBoundingBox, j, ix, 0, j, ix, 1, blockState, blockState, false);
					this.fillWithOutline(iWorld, mutableIntBoundingBox, j, ix, 6, j, ix, 9, blockState, blockState, false);
					this.fillWithOutline(iWorld, mutableIntBoundingBox, j, ix, 14, j, ix, 15, blockState, blockState, false);
				}

				this.fillWithOutline(iWorld, mutableIntBoundingBox, 1, ix, 0, 1, ix, 0, blockState, blockState, false);
				this.fillWithOutline(iWorld, mutableIntBoundingBox, 6, ix, 0, 9, ix, 0, blockState, blockState, false);
				this.fillWithOutline(iWorld, mutableIntBoundingBox, 14, ix, 0, 14, ix, 0, blockState, blockState, false);
				this.fillWithOutline(iWorld, mutableIntBoundingBox, 1, ix, 15, 14, ix, 15, blockState, blockState, false);
			}

			this.fillWithOutline(iWorld, mutableIntBoundingBox, 6, 3, 6, 9, 6, 9, field_14474, field_14474, false);
			this.fillWithOutline(iWorld, mutableIntBoundingBox, 7, 4, 7, 8, 5, 8, Blocks.field_10205.getDefaultState(), Blocks.field_10205.getDefaultState(), false);

			for (int ix = 3; ix <= 6; ix += 3) {
				for (int k = 6; k <= 9; k += 3) {
					this.addBlock(iWorld, field_14471, k, ix, 6, mutableIntBoundingBox);
					this.addBlock(iWorld, field_14471, k, ix, 9, mutableIntBoundingBox);
				}
			}

			this.fillWithOutline(iWorld, mutableIntBoundingBox, 5, 1, 6, 5, 2, 6, field_14476, field_14476, false);
			this.fillWithOutline(iWorld, mutableIntBoundingBox, 5, 1, 9, 5, 2, 9, field_14476, field_14476, false);
			this.fillWithOutline(iWorld, mutableIntBoundingBox, 10, 1, 6, 10, 2, 6, field_14476, field_14476, false);
			this.fillWithOutline(iWorld, mutableIntBoundingBox, 10, 1, 9, 10, 2, 9, field_14476, field_14476, false);
			this.fillWithOutline(iWorld, mutableIntBoundingBox, 6, 1, 5, 6, 2, 5, field_14476, field_14476, false);
			this.fillWithOutline(iWorld, mutableIntBoundingBox, 9, 1, 5, 9, 2, 5, field_14476, field_14476, false);
			this.fillWithOutline(iWorld, mutableIntBoundingBox, 6, 1, 10, 6, 2, 10, field_14476, field_14476, false);
			this.fillWithOutline(iWorld, mutableIntBoundingBox, 9, 1, 10, 9, 2, 10, field_14476, field_14476, false);
			this.fillWithOutline(iWorld, mutableIntBoundingBox, 5, 2, 5, 5, 6, 5, field_14476, field_14476, false);
			this.fillWithOutline(iWorld, mutableIntBoundingBox, 5, 2, 10, 5, 6, 10, field_14476, field_14476, false);
			this.fillWithOutline(iWorld, mutableIntBoundingBox, 10, 2, 5, 10, 6, 5, field_14476, field_14476, false);
			this.fillWithOutline(iWorld, mutableIntBoundingBox, 10, 2, 10, 10, 6, 10, field_14476, field_14476, false);
			this.fillWithOutline(iWorld, mutableIntBoundingBox, 5, 7, 1, 5, 7, 6, field_14476, field_14476, false);
			this.fillWithOutline(iWorld, mutableIntBoundingBox, 10, 7, 1, 10, 7, 6, field_14476, field_14476, false);
			this.fillWithOutline(iWorld, mutableIntBoundingBox, 5, 7, 9, 5, 7, 14, field_14476, field_14476, false);
			this.fillWithOutline(iWorld, mutableIntBoundingBox, 10, 7, 9, 10, 7, 14, field_14476, field_14476, false);
			this.fillWithOutline(iWorld, mutableIntBoundingBox, 1, 7, 5, 6, 7, 5, field_14476, field_14476, false);
			this.fillWithOutline(iWorld, mutableIntBoundingBox, 1, 7, 10, 6, 7, 10, field_14476, field_14476, false);
			this.fillWithOutline(iWorld, mutableIntBoundingBox, 9, 7, 5, 14, 7, 5, field_14476, field_14476, false);
			this.fillWithOutline(iWorld, mutableIntBoundingBox, 9, 7, 10, 14, 7, 10, field_14476, field_14476, false);
			this.fillWithOutline(iWorld, mutableIntBoundingBox, 2, 1, 2, 2, 1, 3, field_14476, field_14476, false);
			this.fillWithOutline(iWorld, mutableIntBoundingBox, 3, 1, 2, 3, 1, 2, field_14476, field_14476, false);
			this.fillWithOutline(iWorld, mutableIntBoundingBox, 13, 1, 2, 13, 1, 3, field_14476, field_14476, false);
			this.fillWithOutline(iWorld, mutableIntBoundingBox, 12, 1, 2, 12, 1, 2, field_14476, field_14476, false);
			this.fillWithOutline(iWorld, mutableIntBoundingBox, 2, 1, 12, 2, 1, 13, field_14476, field_14476, false);
			this.fillWithOutline(iWorld, mutableIntBoundingBox, 3, 1, 13, 3, 1, 13, field_14476, field_14476, false);
			this.fillWithOutline(iWorld, mutableIntBoundingBox, 13, 1, 12, 13, 1, 13, field_14476, field_14476, false);
			this.fillWithOutline(iWorld, mutableIntBoundingBox, 12, 1, 13, 12, 1, 13, field_14476, field_14476, false);
			return true;
		}
	}

	public static class class_3377 extends OceanMonumentGenerator.class_3384 {
		public class_3377(Direction direction, OceanMonumentGenerator.class_3388 arg) {
			super(StructurePieceType.field_16963, 1, direction, arg, 2, 1, 1);
		}

		public class_3377(StructureManager structureManager, CompoundTag compoundTag) {
			super(StructurePieceType.field_16963, compoundTag);
		}

		@Override
		public boolean generate(IWorld iWorld, Random random, MutableIntBoundingBox mutableIntBoundingBox, ChunkPos chunkPos) {
			OceanMonumentGenerator.class_3388 lv = this.field_14479.field_14487[Direction.EAST.getId()];
			OceanMonumentGenerator.class_3388 lv2 = this.field_14479;
			if (this.field_14479.field_14486 / 25 > 0) {
				this.method_14774(iWorld, mutableIntBoundingBox, 8, 0, lv.field_14482[Direction.DOWN.getId()]);
				this.method_14774(iWorld, mutableIntBoundingBox, 0, 0, lv2.field_14482[Direction.DOWN.getId()]);
			}

			if (lv2.field_14487[Direction.UP.getId()] == null) {
				this.method_14771(iWorld, mutableIntBoundingBox, 1, 4, 1, 7, 4, 6, field_14473);
			}

			if (lv.field_14487[Direction.UP.getId()] == null) {
				this.method_14771(iWorld, mutableIntBoundingBox, 8, 4, 1, 14, 4, 6, field_14473);
			}

			this.fillWithOutline(iWorld, mutableIntBoundingBox, 0, 3, 0, 0, 3, 7, field_14476, field_14476, false);
			this.fillWithOutline(iWorld, mutableIntBoundingBox, 15, 3, 0, 15, 3, 7, field_14476, field_14476, false);
			this.fillWithOutline(iWorld, mutableIntBoundingBox, 1, 3, 0, 15, 3, 0, field_14476, field_14476, false);
			this.fillWithOutline(iWorld, mutableIntBoundingBox, 1, 3, 7, 14, 3, 7, field_14476, field_14476, false);
			this.fillWithOutline(iWorld, mutableIntBoundingBox, 0, 2, 0, 0, 2, 7, field_14473, field_14473, false);
			this.fillWithOutline(iWorld, mutableIntBoundingBox, 15, 2, 0, 15, 2, 7, field_14473, field_14473, false);
			this.fillWithOutline(iWorld, mutableIntBoundingBox, 1, 2, 0, 15, 2, 0, field_14473, field_14473, false);
			this.fillWithOutline(iWorld, mutableIntBoundingBox, 1, 2, 7, 14, 2, 7, field_14473, field_14473, false);
			this.fillWithOutline(iWorld, mutableIntBoundingBox, 0, 1, 0, 0, 1, 7, field_14476, field_14476, false);
			this.fillWithOutline(iWorld, mutableIntBoundingBox, 15, 1, 0, 15, 1, 7, field_14476, field_14476, false);
			this.fillWithOutline(iWorld, mutableIntBoundingBox, 1, 1, 0, 15, 1, 0, field_14476, field_14476, false);
			this.fillWithOutline(iWorld, mutableIntBoundingBox, 1, 1, 7, 14, 1, 7, field_14476, field_14476, false);
			this.fillWithOutline(iWorld, mutableIntBoundingBox, 5, 1, 0, 10, 1, 4, field_14476, field_14476, false);
			this.fillWithOutline(iWorld, mutableIntBoundingBox, 6, 2, 0, 9, 2, 3, field_14473, field_14473, false);
			this.fillWithOutline(iWorld, mutableIntBoundingBox, 5, 3, 0, 10, 3, 4, field_14476, field_14476, false);
			this.addBlock(iWorld, field_14471, 6, 2, 3, mutableIntBoundingBox);
			this.addBlock(iWorld, field_14471, 9, 2, 3, mutableIntBoundingBox);
			if (lv2.field_14482[Direction.SOUTH.getId()]) {
				this.method_14773(iWorld, mutableIntBoundingBox, 3, 1, 0, 4, 2, 0);
			}

			if (lv2.field_14482[Direction.NORTH.getId()]) {
				this.method_14773(iWorld, mutableIntBoundingBox, 3, 1, 7, 4, 2, 7);
			}

			if (lv2.field_14482[Direction.WEST.getId()]) {
				this.method_14773(iWorld, mutableIntBoundingBox, 0, 1, 3, 0, 2, 4);
			}

			if (lv.field_14482[Direction.SOUTH.getId()]) {
				this.method_14773(iWorld, mutableIntBoundingBox, 11, 1, 0, 12, 2, 0);
			}

			if (lv.field_14482[Direction.NORTH.getId()]) {
				this.method_14773(iWorld, mutableIntBoundingBox, 11, 1, 7, 12, 2, 7);
			}

			if (lv.field_14482[Direction.EAST.getId()]) {
				this.method_14773(iWorld, mutableIntBoundingBox, 15, 1, 3, 15, 2, 4);
			}

			return true;
		}
	}

	public static class class_3378 extends OceanMonumentGenerator.class_3384 {
		public class_3378(Direction direction, OceanMonumentGenerator.class_3388 arg) {
			super(StructurePieceType.field_16927, 1, direction, arg, 2, 2, 1);
		}

		public class_3378(StructureManager structureManager, CompoundTag compoundTag) {
			super(StructurePieceType.field_16927, compoundTag);
		}

		@Override
		public boolean generate(IWorld iWorld, Random random, MutableIntBoundingBox mutableIntBoundingBox, ChunkPos chunkPos) {
			OceanMonumentGenerator.class_3388 lv = this.field_14479.field_14487[Direction.EAST.getId()];
			OceanMonumentGenerator.class_3388 lv2 = this.field_14479;
			OceanMonumentGenerator.class_3388 lv3 = lv2.field_14487[Direction.UP.getId()];
			OceanMonumentGenerator.class_3388 lv4 = lv.field_14487[Direction.UP.getId()];
			if (this.field_14479.field_14486 / 25 > 0) {
				this.method_14774(iWorld, mutableIntBoundingBox, 8, 0, lv.field_14482[Direction.DOWN.getId()]);
				this.method_14774(iWorld, mutableIntBoundingBox, 0, 0, lv2.field_14482[Direction.DOWN.getId()]);
			}

			if (lv3.field_14487[Direction.UP.getId()] == null) {
				this.method_14771(iWorld, mutableIntBoundingBox, 1, 8, 1, 7, 8, 6, field_14473);
			}

			if (lv4.field_14487[Direction.UP.getId()] == null) {
				this.method_14771(iWorld, mutableIntBoundingBox, 8, 8, 1, 14, 8, 6, field_14473);
			}

			for (int i = 1; i <= 7; i++) {
				BlockState blockState = field_14476;
				if (i == 2 || i == 6) {
					blockState = field_14473;
				}

				this.fillWithOutline(iWorld, mutableIntBoundingBox, 0, i, 0, 0, i, 7, blockState, blockState, false);
				this.fillWithOutline(iWorld, mutableIntBoundingBox, 15, i, 0, 15, i, 7, blockState, blockState, false);
				this.fillWithOutline(iWorld, mutableIntBoundingBox, 1, i, 0, 15, i, 0, blockState, blockState, false);
				this.fillWithOutline(iWorld, mutableIntBoundingBox, 1, i, 7, 14, i, 7, blockState, blockState, false);
			}

			this.fillWithOutline(iWorld, mutableIntBoundingBox, 2, 1, 3, 2, 7, 4, field_14476, field_14476, false);
			this.fillWithOutline(iWorld, mutableIntBoundingBox, 3, 1, 2, 4, 7, 2, field_14476, field_14476, false);
			this.fillWithOutline(iWorld, mutableIntBoundingBox, 3, 1, 5, 4, 7, 5, field_14476, field_14476, false);
			this.fillWithOutline(iWorld, mutableIntBoundingBox, 13, 1, 3, 13, 7, 4, field_14476, field_14476, false);
			this.fillWithOutline(iWorld, mutableIntBoundingBox, 11, 1, 2, 12, 7, 2, field_14476, field_14476, false);
			this.fillWithOutline(iWorld, mutableIntBoundingBox, 11, 1, 5, 12, 7, 5, field_14476, field_14476, false);
			this.fillWithOutline(iWorld, mutableIntBoundingBox, 5, 1, 3, 5, 3, 4, field_14476, field_14476, false);
			this.fillWithOutline(iWorld, mutableIntBoundingBox, 10, 1, 3, 10, 3, 4, field_14476, field_14476, false);
			this.fillWithOutline(iWorld, mutableIntBoundingBox, 5, 7, 2, 10, 7, 5, field_14476, field_14476, false);
			this.fillWithOutline(iWorld, mutableIntBoundingBox, 5, 5, 2, 5, 7, 2, field_14476, field_14476, false);
			this.fillWithOutline(iWorld, mutableIntBoundingBox, 10, 5, 2, 10, 7, 2, field_14476, field_14476, false);
			this.fillWithOutline(iWorld, mutableIntBoundingBox, 5, 5, 5, 5, 7, 5, field_14476, field_14476, false);
			this.fillWithOutline(iWorld, mutableIntBoundingBox, 10, 5, 5, 10, 7, 5, field_14476, field_14476, false);
			this.addBlock(iWorld, field_14476, 6, 6, 2, mutableIntBoundingBox);
			this.addBlock(iWorld, field_14476, 9, 6, 2, mutableIntBoundingBox);
			this.addBlock(iWorld, field_14476, 6, 6, 5, mutableIntBoundingBox);
			this.addBlock(iWorld, field_14476, 9, 6, 5, mutableIntBoundingBox);
			this.fillWithOutline(iWorld, mutableIntBoundingBox, 5, 4, 3, 6, 4, 4, field_14476, field_14476, false);
			this.fillWithOutline(iWorld, mutableIntBoundingBox, 9, 4, 3, 10, 4, 4, field_14476, field_14476, false);
			this.addBlock(iWorld, field_14471, 5, 4, 2, mutableIntBoundingBox);
			this.addBlock(iWorld, field_14471, 5, 4, 5, mutableIntBoundingBox);
			this.addBlock(iWorld, field_14471, 10, 4, 2, mutableIntBoundingBox);
			this.addBlock(iWorld, field_14471, 10, 4, 5, mutableIntBoundingBox);
			if (lv2.field_14482[Direction.SOUTH.getId()]) {
				this.method_14773(iWorld, mutableIntBoundingBox, 3, 1, 0, 4, 2, 0);
			}

			if (lv2.field_14482[Direction.NORTH.getId()]) {
				this.method_14773(iWorld, mutableIntBoundingBox, 3, 1, 7, 4, 2, 7);
			}

			if (lv2.field_14482[Direction.WEST.getId()]) {
				this.method_14773(iWorld, mutableIntBoundingBox, 0, 1, 3, 0, 2, 4);
			}

			if (lv.field_14482[Direction.SOUTH.getId()]) {
				this.method_14773(iWorld, mutableIntBoundingBox, 11, 1, 0, 12, 2, 0);
			}

			if (lv.field_14482[Direction.NORTH.getId()]) {
				this.method_14773(iWorld, mutableIntBoundingBox, 11, 1, 7, 12, 2, 7);
			}

			if (lv.field_14482[Direction.EAST.getId()]) {
				this.method_14773(iWorld, mutableIntBoundingBox, 15, 1, 3, 15, 2, 4);
			}

			if (lv3.field_14482[Direction.SOUTH.getId()]) {
				this.method_14773(iWorld, mutableIntBoundingBox, 3, 5, 0, 4, 6, 0);
			}

			if (lv3.field_14482[Direction.NORTH.getId()]) {
				this.method_14773(iWorld, mutableIntBoundingBox, 3, 5, 7, 4, 6, 7);
			}

			if (lv3.field_14482[Direction.WEST.getId()]) {
				this.method_14773(iWorld, mutableIntBoundingBox, 0, 5, 3, 0, 6, 4);
			}

			if (lv4.field_14482[Direction.SOUTH.getId()]) {
				this.method_14773(iWorld, mutableIntBoundingBox, 11, 5, 0, 12, 6, 0);
			}

			if (lv4.field_14482[Direction.NORTH.getId()]) {
				this.method_14773(iWorld, mutableIntBoundingBox, 11, 5, 7, 12, 6, 7);
			}

			if (lv4.field_14482[Direction.EAST.getId()]) {
				this.method_14773(iWorld, mutableIntBoundingBox, 15, 5, 3, 15, 6, 4);
			}

			return true;
		}
	}

	public static class class_3379 extends OceanMonumentGenerator.class_3384 {
		public class_3379(Direction direction, OceanMonumentGenerator.class_3388 arg) {
			super(StructurePieceType.field_16946, 1, direction, arg, 1, 2, 1);
		}

		public class_3379(StructureManager structureManager, CompoundTag compoundTag) {
			super(StructurePieceType.field_16946, compoundTag);
		}

		@Override
		public boolean generate(IWorld iWorld, Random random, MutableIntBoundingBox mutableIntBoundingBox, ChunkPos chunkPos) {
			if (this.field_14479.field_14486 / 25 > 0) {
				this.method_14774(iWorld, mutableIntBoundingBox, 0, 0, this.field_14479.field_14482[Direction.DOWN.getId()]);
			}

			OceanMonumentGenerator.class_3388 lv = this.field_14479.field_14487[Direction.UP.getId()];
			if (lv.field_14487[Direction.UP.getId()] == null) {
				this.method_14771(iWorld, mutableIntBoundingBox, 1, 8, 1, 6, 8, 6, field_14473);
			}

			this.fillWithOutline(iWorld, mutableIntBoundingBox, 0, 4, 0, 0, 4, 7, field_14476, field_14476, false);
			this.fillWithOutline(iWorld, mutableIntBoundingBox, 7, 4, 0, 7, 4, 7, field_14476, field_14476, false);
			this.fillWithOutline(iWorld, mutableIntBoundingBox, 1, 4, 0, 6, 4, 0, field_14476, field_14476, false);
			this.fillWithOutline(iWorld, mutableIntBoundingBox, 1, 4, 7, 6, 4, 7, field_14476, field_14476, false);
			this.fillWithOutline(iWorld, mutableIntBoundingBox, 2, 4, 1, 2, 4, 2, field_14476, field_14476, false);
			this.fillWithOutline(iWorld, mutableIntBoundingBox, 1, 4, 2, 1, 4, 2, field_14476, field_14476, false);
			this.fillWithOutline(iWorld, mutableIntBoundingBox, 5, 4, 1, 5, 4, 2, field_14476, field_14476, false);
			this.fillWithOutline(iWorld, mutableIntBoundingBox, 6, 4, 2, 6, 4, 2, field_14476, field_14476, false);
			this.fillWithOutline(iWorld, mutableIntBoundingBox, 2, 4, 5, 2, 4, 6, field_14476, field_14476, false);
			this.fillWithOutline(iWorld, mutableIntBoundingBox, 1, 4, 5, 1, 4, 5, field_14476, field_14476, false);
			this.fillWithOutline(iWorld, mutableIntBoundingBox, 5, 4, 5, 5, 4, 6, field_14476, field_14476, false);
			this.fillWithOutline(iWorld, mutableIntBoundingBox, 6, 4, 5, 6, 4, 5, field_14476, field_14476, false);
			OceanMonumentGenerator.class_3388 lv2 = this.field_14479;

			for (int i = 1; i <= 5; i += 4) {
				int j = 0;
				if (lv2.field_14482[Direction.SOUTH.getId()]) {
					this.fillWithOutline(iWorld, mutableIntBoundingBox, 2, i, j, 2, i + 2, j, field_14476, field_14476, false);
					this.fillWithOutline(iWorld, mutableIntBoundingBox, 5, i, j, 5, i + 2, j, field_14476, field_14476, false);
					this.fillWithOutline(iWorld, mutableIntBoundingBox, 3, i + 2, j, 4, i + 2, j, field_14476, field_14476, false);
				} else {
					this.fillWithOutline(iWorld, mutableIntBoundingBox, 0, i, j, 7, i + 2, j, field_14476, field_14476, false);
					this.fillWithOutline(iWorld, mutableIntBoundingBox, 0, i + 1, j, 7, i + 1, j, field_14473, field_14473, false);
				}

				int var10 = 7;
				if (lv2.field_14482[Direction.NORTH.getId()]) {
					this.fillWithOutline(iWorld, mutableIntBoundingBox, 2, i, var10, 2, i + 2, var10, field_14476, field_14476, false);
					this.fillWithOutline(iWorld, mutableIntBoundingBox, 5, i, var10, 5, i + 2, var10, field_14476, field_14476, false);
					this.fillWithOutline(iWorld, mutableIntBoundingBox, 3, i + 2, var10, 4, i + 2, var10, field_14476, field_14476, false);
				} else {
					this.fillWithOutline(iWorld, mutableIntBoundingBox, 0, i, var10, 7, i + 2, var10, field_14476, field_14476, false);
					this.fillWithOutline(iWorld, mutableIntBoundingBox, 0, i + 1, var10, 7, i + 1, var10, field_14473, field_14473, false);
				}

				int k = 0;
				if (lv2.field_14482[Direction.WEST.getId()]) {
					this.fillWithOutline(iWorld, mutableIntBoundingBox, k, i, 2, k, i + 2, 2, field_14476, field_14476, false);
					this.fillWithOutline(iWorld, mutableIntBoundingBox, k, i, 5, k, i + 2, 5, field_14476, field_14476, false);
					this.fillWithOutline(iWorld, mutableIntBoundingBox, k, i + 2, 3, k, i + 2, 4, field_14476, field_14476, false);
				} else {
					this.fillWithOutline(iWorld, mutableIntBoundingBox, k, i, 0, k, i + 2, 7, field_14476, field_14476, false);
					this.fillWithOutline(iWorld, mutableIntBoundingBox, k, i + 1, 0, k, i + 1, 7, field_14473, field_14473, false);
				}

				int var11 = 7;
				if (lv2.field_14482[Direction.EAST.getId()]) {
					this.fillWithOutline(iWorld, mutableIntBoundingBox, var11, i, 2, var11, i + 2, 2, field_14476, field_14476, false);
					this.fillWithOutline(iWorld, mutableIntBoundingBox, var11, i, 5, var11, i + 2, 5, field_14476, field_14476, false);
					this.fillWithOutline(iWorld, mutableIntBoundingBox, var11, i + 2, 3, var11, i + 2, 4, field_14476, field_14476, false);
				} else {
					this.fillWithOutline(iWorld, mutableIntBoundingBox, var11, i, 0, var11, i + 2, 7, field_14476, field_14476, false);
					this.fillWithOutline(iWorld, mutableIntBoundingBox, var11, i + 1, 0, var11, i + 1, 7, field_14473, field_14473, false);
				}

				lv2 = lv;
			}

			return true;
		}
	}

	public static class class_3380 extends OceanMonumentGenerator.class_3384 {
		public class_3380(Direction direction, OceanMonumentGenerator.class_3388 arg) {
			super(StructurePieceType.field_16970, 1, direction, arg, 1, 2, 2);
		}

		public class_3380(StructureManager structureManager, CompoundTag compoundTag) {
			super(StructurePieceType.field_16970, compoundTag);
		}

		@Override
		public boolean generate(IWorld iWorld, Random random, MutableIntBoundingBox mutableIntBoundingBox, ChunkPos chunkPos) {
			OceanMonumentGenerator.class_3388 lv = this.field_14479.field_14487[Direction.NORTH.getId()];
			OceanMonumentGenerator.class_3388 lv2 = this.field_14479;
			OceanMonumentGenerator.class_3388 lv3 = lv.field_14487[Direction.UP.getId()];
			OceanMonumentGenerator.class_3388 lv4 = lv2.field_14487[Direction.UP.getId()];
			if (this.field_14479.field_14486 / 25 > 0) {
				this.method_14774(iWorld, mutableIntBoundingBox, 0, 8, lv.field_14482[Direction.DOWN.getId()]);
				this.method_14774(iWorld, mutableIntBoundingBox, 0, 0, lv2.field_14482[Direction.DOWN.getId()]);
			}

			if (lv4.field_14487[Direction.UP.getId()] == null) {
				this.method_14771(iWorld, mutableIntBoundingBox, 1, 8, 1, 6, 8, 7, field_14473);
			}

			if (lv3.field_14487[Direction.UP.getId()] == null) {
				this.method_14771(iWorld, mutableIntBoundingBox, 1, 8, 8, 6, 8, 14, field_14473);
			}

			for (int i = 1; i <= 7; i++) {
				BlockState blockState = field_14476;
				if (i == 2 || i == 6) {
					blockState = field_14473;
				}

				this.fillWithOutline(iWorld, mutableIntBoundingBox, 0, i, 0, 0, i, 15, blockState, blockState, false);
				this.fillWithOutline(iWorld, mutableIntBoundingBox, 7, i, 0, 7, i, 15, blockState, blockState, false);
				this.fillWithOutline(iWorld, mutableIntBoundingBox, 1, i, 0, 6, i, 0, blockState, blockState, false);
				this.fillWithOutline(iWorld, mutableIntBoundingBox, 1, i, 15, 6, i, 15, blockState, blockState, false);
			}

			for (int i = 1; i <= 7; i++) {
				BlockState blockState = field_14474;
				if (i == 2 || i == 6) {
					blockState = field_14471;
				}

				this.fillWithOutline(iWorld, mutableIntBoundingBox, 3, i, 7, 4, i, 8, blockState, blockState, false);
			}

			if (lv2.field_14482[Direction.SOUTH.getId()]) {
				this.method_14773(iWorld, mutableIntBoundingBox, 3, 1, 0, 4, 2, 0);
			}

			if (lv2.field_14482[Direction.EAST.getId()]) {
				this.method_14773(iWorld, mutableIntBoundingBox, 7, 1, 3, 7, 2, 4);
			}

			if (lv2.field_14482[Direction.WEST.getId()]) {
				this.method_14773(iWorld, mutableIntBoundingBox, 0, 1, 3, 0, 2, 4);
			}

			if (lv.field_14482[Direction.NORTH.getId()]) {
				this.method_14773(iWorld, mutableIntBoundingBox, 3, 1, 15, 4, 2, 15);
			}

			if (lv.field_14482[Direction.WEST.getId()]) {
				this.method_14773(iWorld, mutableIntBoundingBox, 0, 1, 11, 0, 2, 12);
			}

			if (lv.field_14482[Direction.EAST.getId()]) {
				this.method_14773(iWorld, mutableIntBoundingBox, 7, 1, 11, 7, 2, 12);
			}

			if (lv4.field_14482[Direction.SOUTH.getId()]) {
				this.method_14773(iWorld, mutableIntBoundingBox, 3, 5, 0, 4, 6, 0);
			}

			if (lv4.field_14482[Direction.EAST.getId()]) {
				this.method_14773(iWorld, mutableIntBoundingBox, 7, 5, 3, 7, 6, 4);
				this.fillWithOutline(iWorld, mutableIntBoundingBox, 5, 4, 2, 6, 4, 5, field_14476, field_14476, false);
				this.fillWithOutline(iWorld, mutableIntBoundingBox, 6, 1, 2, 6, 3, 2, field_14476, field_14476, false);
				this.fillWithOutline(iWorld, mutableIntBoundingBox, 6, 1, 5, 6, 3, 5, field_14476, field_14476, false);
			}

			if (lv4.field_14482[Direction.WEST.getId()]) {
				this.method_14773(iWorld, mutableIntBoundingBox, 0, 5, 3, 0, 6, 4);
				this.fillWithOutline(iWorld, mutableIntBoundingBox, 1, 4, 2, 2, 4, 5, field_14476, field_14476, false);
				this.fillWithOutline(iWorld, mutableIntBoundingBox, 1, 1, 2, 1, 3, 2, field_14476, field_14476, false);
				this.fillWithOutline(iWorld, mutableIntBoundingBox, 1, 1, 5, 1, 3, 5, field_14476, field_14476, false);
			}

			if (lv3.field_14482[Direction.NORTH.getId()]) {
				this.method_14773(iWorld, mutableIntBoundingBox, 3, 5, 15, 4, 6, 15);
			}

			if (lv3.field_14482[Direction.WEST.getId()]) {
				this.method_14773(iWorld, mutableIntBoundingBox, 0, 5, 11, 0, 6, 12);
				this.fillWithOutline(iWorld, mutableIntBoundingBox, 1, 4, 10, 2, 4, 13, field_14476, field_14476, false);
				this.fillWithOutline(iWorld, mutableIntBoundingBox, 1, 1, 10, 1, 3, 10, field_14476, field_14476, false);
				this.fillWithOutline(iWorld, mutableIntBoundingBox, 1, 1, 13, 1, 3, 13, field_14476, field_14476, false);
			}

			if (lv3.field_14482[Direction.EAST.getId()]) {
				this.method_14773(iWorld, mutableIntBoundingBox, 7, 5, 11, 7, 6, 12);
				this.fillWithOutline(iWorld, mutableIntBoundingBox, 5, 4, 10, 6, 4, 13, field_14476, field_14476, false);
				this.fillWithOutline(iWorld, mutableIntBoundingBox, 6, 1, 10, 6, 3, 10, field_14476, field_14476, false);
				this.fillWithOutline(iWorld, mutableIntBoundingBox, 6, 1, 13, 6, 3, 13, field_14476, field_14476, false);
			}

			return true;
		}
	}

	public static class class_3381 extends OceanMonumentGenerator.class_3384 {
		public class_3381(Direction direction, OceanMonumentGenerator.class_3388 arg) {
			super(StructurePieceType.field_16925, 1, direction, arg, 1, 1, 2);
		}

		public class_3381(StructureManager structureManager, CompoundTag compoundTag) {
			super(StructurePieceType.field_16925, compoundTag);
		}

		@Override
		public boolean generate(IWorld iWorld, Random random, MutableIntBoundingBox mutableIntBoundingBox, ChunkPos chunkPos) {
			OceanMonumentGenerator.class_3388 lv = this.field_14479.field_14487[Direction.NORTH.getId()];
			OceanMonumentGenerator.class_3388 lv2 = this.field_14479;
			if (this.field_14479.field_14486 / 25 > 0) {
				this.method_14774(iWorld, mutableIntBoundingBox, 0, 8, lv.field_14482[Direction.DOWN.getId()]);
				this.method_14774(iWorld, mutableIntBoundingBox, 0, 0, lv2.field_14482[Direction.DOWN.getId()]);
			}

			if (lv2.field_14487[Direction.UP.getId()] == null) {
				this.method_14771(iWorld, mutableIntBoundingBox, 1, 4, 1, 6, 4, 7, field_14473);
			}

			if (lv.field_14487[Direction.UP.getId()] == null) {
				this.method_14771(iWorld, mutableIntBoundingBox, 1, 4, 8, 6, 4, 14, field_14473);
			}

			this.fillWithOutline(iWorld, mutableIntBoundingBox, 0, 3, 0, 0, 3, 15, field_14476, field_14476, false);
			this.fillWithOutline(iWorld, mutableIntBoundingBox, 7, 3, 0, 7, 3, 15, field_14476, field_14476, false);
			this.fillWithOutline(iWorld, mutableIntBoundingBox, 1, 3, 0, 7, 3, 0, field_14476, field_14476, false);
			this.fillWithOutline(iWorld, mutableIntBoundingBox, 1, 3, 15, 6, 3, 15, field_14476, field_14476, false);
			this.fillWithOutline(iWorld, mutableIntBoundingBox, 0, 2, 0, 0, 2, 15, field_14473, field_14473, false);
			this.fillWithOutline(iWorld, mutableIntBoundingBox, 7, 2, 0, 7, 2, 15, field_14473, field_14473, false);
			this.fillWithOutline(iWorld, mutableIntBoundingBox, 1, 2, 0, 7, 2, 0, field_14473, field_14473, false);
			this.fillWithOutline(iWorld, mutableIntBoundingBox, 1, 2, 15, 6, 2, 15, field_14473, field_14473, false);
			this.fillWithOutline(iWorld, mutableIntBoundingBox, 0, 1, 0, 0, 1, 15, field_14476, field_14476, false);
			this.fillWithOutline(iWorld, mutableIntBoundingBox, 7, 1, 0, 7, 1, 15, field_14476, field_14476, false);
			this.fillWithOutline(iWorld, mutableIntBoundingBox, 1, 1, 0, 7, 1, 0, field_14476, field_14476, false);
			this.fillWithOutline(iWorld, mutableIntBoundingBox, 1, 1, 15, 6, 1, 15, field_14476, field_14476, false);
			this.fillWithOutline(iWorld, mutableIntBoundingBox, 1, 1, 1, 1, 1, 2, field_14476, field_14476, false);
			this.fillWithOutline(iWorld, mutableIntBoundingBox, 6, 1, 1, 6, 1, 2, field_14476, field_14476, false);
			this.fillWithOutline(iWorld, mutableIntBoundingBox, 1, 3, 1, 1, 3, 2, field_14476, field_14476, false);
			this.fillWithOutline(iWorld, mutableIntBoundingBox, 6, 3, 1, 6, 3, 2, field_14476, field_14476, false);
			this.fillWithOutline(iWorld, mutableIntBoundingBox, 1, 1, 13, 1, 1, 14, field_14476, field_14476, false);
			this.fillWithOutline(iWorld, mutableIntBoundingBox, 6, 1, 13, 6, 1, 14, field_14476, field_14476, false);
			this.fillWithOutline(iWorld, mutableIntBoundingBox, 1, 3, 13, 1, 3, 14, field_14476, field_14476, false);
			this.fillWithOutline(iWorld, mutableIntBoundingBox, 6, 3, 13, 6, 3, 14, field_14476, field_14476, false);
			this.fillWithOutline(iWorld, mutableIntBoundingBox, 2, 1, 6, 2, 3, 6, field_14476, field_14476, false);
			this.fillWithOutline(iWorld, mutableIntBoundingBox, 5, 1, 6, 5, 3, 6, field_14476, field_14476, false);
			this.fillWithOutline(iWorld, mutableIntBoundingBox, 2, 1, 9, 2, 3, 9, field_14476, field_14476, false);
			this.fillWithOutline(iWorld, mutableIntBoundingBox, 5, 1, 9, 5, 3, 9, field_14476, field_14476, false);
			this.fillWithOutline(iWorld, mutableIntBoundingBox, 3, 2, 6, 4, 2, 6, field_14476, field_14476, false);
			this.fillWithOutline(iWorld, mutableIntBoundingBox, 3, 2, 9, 4, 2, 9, field_14476, field_14476, false);
			this.fillWithOutline(iWorld, mutableIntBoundingBox, 2, 2, 7, 2, 2, 8, field_14476, field_14476, false);
			this.fillWithOutline(iWorld, mutableIntBoundingBox, 5, 2, 7, 5, 2, 8, field_14476, field_14476, false);
			this.addBlock(iWorld, field_14471, 2, 2, 5, mutableIntBoundingBox);
			this.addBlock(iWorld, field_14471, 5, 2, 5, mutableIntBoundingBox);
			this.addBlock(iWorld, field_14471, 2, 2, 10, mutableIntBoundingBox);
			this.addBlock(iWorld, field_14471, 5, 2, 10, mutableIntBoundingBox);
			this.addBlock(iWorld, field_14476, 2, 3, 5, mutableIntBoundingBox);
			this.addBlock(iWorld, field_14476, 5, 3, 5, mutableIntBoundingBox);
			this.addBlock(iWorld, field_14476, 2, 3, 10, mutableIntBoundingBox);
			this.addBlock(iWorld, field_14476, 5, 3, 10, mutableIntBoundingBox);
			if (lv2.field_14482[Direction.SOUTH.getId()]) {
				this.method_14773(iWorld, mutableIntBoundingBox, 3, 1, 0, 4, 2, 0);
			}

			if (lv2.field_14482[Direction.EAST.getId()]) {
				this.method_14773(iWorld, mutableIntBoundingBox, 7, 1, 3, 7, 2, 4);
			}

			if (lv2.field_14482[Direction.WEST.getId()]) {
				this.method_14773(iWorld, mutableIntBoundingBox, 0, 1, 3, 0, 2, 4);
			}

			if (lv.field_14482[Direction.NORTH.getId()]) {
				this.method_14773(iWorld, mutableIntBoundingBox, 3, 1, 15, 4, 2, 15);
			}

			if (lv.field_14482[Direction.WEST.getId()]) {
				this.method_14773(iWorld, mutableIntBoundingBox, 0, 1, 11, 0, 2, 12);
			}

			if (lv.field_14482[Direction.EAST.getId()]) {
				this.method_14773(iWorld, mutableIntBoundingBox, 7, 1, 11, 7, 2, 12);
			}

			return true;
		}
	}

	public abstract static class class_3384 extends StructurePiece {
		protected static final BlockState field_14473 = Blocks.field_10135.getDefaultState();
		protected static final BlockState field_14476 = Blocks.field_10006.getDefaultState();
		protected static final BlockState field_14474 = Blocks.field_10297.getDefaultState();
		protected static final BlockState field_14470 = field_14476;
		protected static final BlockState field_14471 = Blocks.field_10174.getDefaultState();
		protected static final BlockState field_14475 = Blocks.field_10382.getDefaultState();
		protected static final Set<Block> field_14472 = ImmutableSet.<Block>builder()
			.add(Blocks.field_10295)
			.add(Blocks.field_10225)
			.add(Blocks.field_10384)
			.add(field_14475.getBlock())
			.build();
		protected static final int field_14469 = method_14770(2, 0, 0);
		protected static final int field_14468 = method_14770(2, 2, 0);
		protected static final int field_14478 = method_14770(0, 1, 0);
		protected static final int field_14477 = method_14770(4, 1, 0);
		protected OceanMonumentGenerator.class_3388 field_14479;

		protected static final int method_14770(int i, int j, int k) {
			return j * 25 + k * 5 + i;
		}

		public class_3384(StructurePieceType structurePieceType, int i) {
			super(structurePieceType, i);
		}

		public class_3384(StructurePieceType structurePieceType, Direction direction, MutableIntBoundingBox mutableIntBoundingBox) {
			super(structurePieceType, 1);
			this.setOrientation(direction);
			this.boundingBox = mutableIntBoundingBox;
		}

		protected class_3384(StructurePieceType structurePieceType, int i, Direction direction, OceanMonumentGenerator.class_3388 arg, int j, int k, int l) {
			super(structurePieceType, i);
			this.setOrientation(direction);
			this.field_14479 = arg;
			int m = arg.field_14486;
			int n = m % 5;
			int o = m / 5 % 5;
			int p = m / 25;
			if (direction != Direction.NORTH && direction != Direction.SOUTH) {
				this.boundingBox = new MutableIntBoundingBox(0, 0, 0, l * 8 - 1, k * 4 - 1, j * 8 - 1);
			} else {
				this.boundingBox = new MutableIntBoundingBox(0, 0, 0, j * 8 - 1, k * 4 - 1, l * 8 - 1);
			}

			switch (direction) {
				case NORTH:
					this.boundingBox.translate(n * 8, p * 4, -(o + l) * 8 + 1);
					break;
				case SOUTH:
					this.boundingBox.translate(n * 8, p * 4, o * 8);
					break;
				case WEST:
					this.boundingBox.translate(-(o + l) * 8 + 1, p * 4, n * 8);
					break;
				default:
					this.boundingBox.translate(o * 8, p * 4, n * 8);
			}
		}

		public class_3384(StructurePieceType structurePieceType, CompoundTag compoundTag) {
			super(structurePieceType, compoundTag);
		}

		@Override
		protected void toNbt(CompoundTag compoundTag) {
		}

		protected void method_14773(IWorld iWorld, MutableIntBoundingBox mutableIntBoundingBox, int i, int j, int k, int l, int m, int n) {
			for (int o = j; o <= m; o++) {
				for (int p = i; p <= l; p++) {
					for (int q = k; q <= n; q++) {
						BlockState blockState = this.getBlockAt(iWorld, p, o, q, mutableIntBoundingBox);
						if (!field_14472.contains(blockState.getBlock())) {
							if (this.applyYTransform(o) >= iWorld.getSeaLevel() && blockState != field_14475) {
								this.addBlock(iWorld, Blocks.field_10124.getDefaultState(), p, o, q, mutableIntBoundingBox);
							} else {
								this.addBlock(iWorld, field_14475, p, o, q, mutableIntBoundingBox);
							}
						}
					}
				}
			}
		}

		protected void method_14774(IWorld iWorld, MutableIntBoundingBox mutableIntBoundingBox, int i, int j, boolean bl) {
			if (bl) {
				this.fillWithOutline(iWorld, mutableIntBoundingBox, i + 0, 0, j + 0, i + 2, 0, j + 8 - 1, field_14473, field_14473, false);
				this.fillWithOutline(iWorld, mutableIntBoundingBox, i + 5, 0, j + 0, i + 8 - 1, 0, j + 8 - 1, field_14473, field_14473, false);
				this.fillWithOutline(iWorld, mutableIntBoundingBox, i + 3, 0, j + 0, i + 4, 0, j + 2, field_14473, field_14473, false);
				this.fillWithOutline(iWorld, mutableIntBoundingBox, i + 3, 0, j + 5, i + 4, 0, j + 8 - 1, field_14473, field_14473, false);
				this.fillWithOutline(iWorld, mutableIntBoundingBox, i + 3, 0, j + 2, i + 4, 0, j + 2, field_14476, field_14476, false);
				this.fillWithOutline(iWorld, mutableIntBoundingBox, i + 3, 0, j + 5, i + 4, 0, j + 5, field_14476, field_14476, false);
				this.fillWithOutline(iWorld, mutableIntBoundingBox, i + 2, 0, j + 3, i + 2, 0, j + 4, field_14476, field_14476, false);
				this.fillWithOutline(iWorld, mutableIntBoundingBox, i + 5, 0, j + 3, i + 5, 0, j + 4, field_14476, field_14476, false);
			} else {
				this.fillWithOutline(iWorld, mutableIntBoundingBox, i + 0, 0, j + 0, i + 8 - 1, 0, j + 8 - 1, field_14473, field_14473, false);
			}
		}

		protected void method_14771(IWorld iWorld, MutableIntBoundingBox mutableIntBoundingBox, int i, int j, int k, int l, int m, int n, BlockState blockState) {
			for (int o = j; o <= m; o++) {
				for (int p = i; p <= l; p++) {
					for (int q = k; q <= n; q++) {
						if (this.getBlockAt(iWorld, p, o, q, mutableIntBoundingBox) == field_14475) {
							this.addBlock(iWorld, blockState, p, o, q, mutableIntBoundingBox);
						}
					}
				}
			}
		}

		protected boolean method_14775(MutableIntBoundingBox mutableIntBoundingBox, int i, int j, int k, int l) {
			int m = this.applyXTransform(i, j);
			int n = this.applyZTransform(i, j);
			int o = this.applyXTransform(k, l);
			int p = this.applyZTransform(k, l);
			return mutableIntBoundingBox.intersectsXZ(Math.min(m, o), Math.min(n, p), Math.max(m, o), Math.max(n, p));
		}

		protected boolean method_14772(IWorld iWorld, MutableIntBoundingBox mutableIntBoundingBox, int i, int j, int k) {
			int l = this.applyXTransform(i, k);
			int m = this.applyYTransform(j);
			int n = this.applyZTransform(i, k);
			if (mutableIntBoundingBox.contains(new BlockPos(l, m, n))) {
				ElderGuardianEntity elderGuardianEntity = EntityType.ELDER_GUARDIAN.create(iWorld.getWorld());
				elderGuardianEntity.heal(elderGuardianEntity.getHealthMaximum());
				elderGuardianEntity.setPositionAndAngles((double)l + 0.5, (double)m, (double)n + 0.5, 0.0F, 0.0F);
				elderGuardianEntity.initialize(iWorld, iWorld.getLocalDifficulty(new BlockPos(elderGuardianEntity)), SpawnType.field_16474, null, null);
				iWorld.spawnEntity(elderGuardianEntity);
				return true;
			} else {
				return false;
			}
		}
	}

	public static class class_3387 extends OceanMonumentGenerator.class_3384 {
		private int field_14481;

		public class_3387(Direction direction, MutableIntBoundingBox mutableIntBoundingBox, int i) {
			super(StructurePieceType.field_16957, direction, mutableIntBoundingBox);
			this.field_14481 = i & 1;
		}

		public class_3387(StructureManager structureManager, CompoundTag compoundTag) {
			super(StructurePieceType.field_16957, compoundTag);
		}

		@Override
		public boolean generate(IWorld iWorld, Random random, MutableIntBoundingBox mutableIntBoundingBox, ChunkPos chunkPos) {
			if (this.field_14481 == 0) {
				for (int i = 0; i < 4; i++) {
					this.fillWithOutline(iWorld, mutableIntBoundingBox, 10 - i, 3 - i, 20 - i, 12 + i, 3 - i, 20, field_14476, field_14476, false);
				}

				this.fillWithOutline(iWorld, mutableIntBoundingBox, 7, 0, 6, 15, 0, 16, field_14476, field_14476, false);
				this.fillWithOutline(iWorld, mutableIntBoundingBox, 6, 0, 6, 6, 3, 20, field_14476, field_14476, false);
				this.fillWithOutline(iWorld, mutableIntBoundingBox, 16, 0, 6, 16, 3, 20, field_14476, field_14476, false);
				this.fillWithOutline(iWorld, mutableIntBoundingBox, 7, 1, 7, 7, 1, 20, field_14476, field_14476, false);
				this.fillWithOutline(iWorld, mutableIntBoundingBox, 15, 1, 7, 15, 1, 20, field_14476, field_14476, false);
				this.fillWithOutline(iWorld, mutableIntBoundingBox, 7, 1, 6, 9, 3, 6, field_14476, field_14476, false);
				this.fillWithOutline(iWorld, mutableIntBoundingBox, 13, 1, 6, 15, 3, 6, field_14476, field_14476, false);
				this.fillWithOutline(iWorld, mutableIntBoundingBox, 8, 1, 7, 9, 1, 7, field_14476, field_14476, false);
				this.fillWithOutline(iWorld, mutableIntBoundingBox, 13, 1, 7, 14, 1, 7, field_14476, field_14476, false);
				this.fillWithOutline(iWorld, mutableIntBoundingBox, 9, 0, 5, 13, 0, 5, field_14476, field_14476, false);
				this.fillWithOutline(iWorld, mutableIntBoundingBox, 10, 0, 7, 12, 0, 7, field_14474, field_14474, false);
				this.fillWithOutline(iWorld, mutableIntBoundingBox, 8, 0, 10, 8, 0, 12, field_14474, field_14474, false);
				this.fillWithOutline(iWorld, mutableIntBoundingBox, 14, 0, 10, 14, 0, 12, field_14474, field_14474, false);

				for (int i = 18; i >= 7; i -= 3) {
					this.addBlock(iWorld, field_14471, 6, 3, i, mutableIntBoundingBox);
					this.addBlock(iWorld, field_14471, 16, 3, i, mutableIntBoundingBox);
				}

				this.addBlock(iWorld, field_14471, 10, 0, 10, mutableIntBoundingBox);
				this.addBlock(iWorld, field_14471, 12, 0, 10, mutableIntBoundingBox);
				this.addBlock(iWorld, field_14471, 10, 0, 12, mutableIntBoundingBox);
				this.addBlock(iWorld, field_14471, 12, 0, 12, mutableIntBoundingBox);
				this.addBlock(iWorld, field_14471, 8, 3, 6, mutableIntBoundingBox);
				this.addBlock(iWorld, field_14471, 14, 3, 6, mutableIntBoundingBox);
				this.addBlock(iWorld, field_14476, 4, 2, 4, mutableIntBoundingBox);
				this.addBlock(iWorld, field_14471, 4, 1, 4, mutableIntBoundingBox);
				this.addBlock(iWorld, field_14476, 4, 0, 4, mutableIntBoundingBox);
				this.addBlock(iWorld, field_14476, 18, 2, 4, mutableIntBoundingBox);
				this.addBlock(iWorld, field_14471, 18, 1, 4, mutableIntBoundingBox);
				this.addBlock(iWorld, field_14476, 18, 0, 4, mutableIntBoundingBox);
				this.addBlock(iWorld, field_14476, 4, 2, 18, mutableIntBoundingBox);
				this.addBlock(iWorld, field_14471, 4, 1, 18, mutableIntBoundingBox);
				this.addBlock(iWorld, field_14476, 4, 0, 18, mutableIntBoundingBox);
				this.addBlock(iWorld, field_14476, 18, 2, 18, mutableIntBoundingBox);
				this.addBlock(iWorld, field_14471, 18, 1, 18, mutableIntBoundingBox);
				this.addBlock(iWorld, field_14476, 18, 0, 18, mutableIntBoundingBox);
				this.addBlock(iWorld, field_14476, 9, 7, 20, mutableIntBoundingBox);
				this.addBlock(iWorld, field_14476, 13, 7, 20, mutableIntBoundingBox);
				this.fillWithOutline(iWorld, mutableIntBoundingBox, 6, 0, 21, 7, 4, 21, field_14476, field_14476, false);
				this.fillWithOutline(iWorld, mutableIntBoundingBox, 15, 0, 21, 16, 4, 21, field_14476, field_14476, false);
				this.method_14772(iWorld, mutableIntBoundingBox, 11, 2, 16);
			} else if (this.field_14481 == 1) {
				this.fillWithOutline(iWorld, mutableIntBoundingBox, 9, 3, 18, 13, 3, 20, field_14476, field_14476, false);
				this.fillWithOutline(iWorld, mutableIntBoundingBox, 9, 0, 18, 9, 2, 18, field_14476, field_14476, false);
				this.fillWithOutline(iWorld, mutableIntBoundingBox, 13, 0, 18, 13, 2, 18, field_14476, field_14476, false);
				int i = 9;
				int j = 20;
				int k = 5;

				for (int l = 0; l < 2; l++) {
					this.addBlock(iWorld, field_14476, i, 6, 20, mutableIntBoundingBox);
					this.addBlock(iWorld, field_14471, i, 5, 20, mutableIntBoundingBox);
					this.addBlock(iWorld, field_14476, i, 4, 20, mutableIntBoundingBox);
					i = 13;
				}

				this.fillWithOutline(iWorld, mutableIntBoundingBox, 7, 3, 7, 15, 3, 14, field_14476, field_14476, false);
				int var11 = 10;

				for (int l = 0; l < 2; l++) {
					this.fillWithOutline(iWorld, mutableIntBoundingBox, var11, 0, 10, var11, 6, 10, field_14476, field_14476, false);
					this.fillWithOutline(iWorld, mutableIntBoundingBox, var11, 0, 12, var11, 6, 12, field_14476, field_14476, false);
					this.addBlock(iWorld, field_14471, var11, 0, 10, mutableIntBoundingBox);
					this.addBlock(iWorld, field_14471, var11, 0, 12, mutableIntBoundingBox);
					this.addBlock(iWorld, field_14471, var11, 4, 10, mutableIntBoundingBox);
					this.addBlock(iWorld, field_14471, var11, 4, 12, mutableIntBoundingBox);
					var11 = 12;
				}

				var11 = 8;

				for (int l = 0; l < 2; l++) {
					this.fillWithOutline(iWorld, mutableIntBoundingBox, var11, 0, 7, var11, 2, 7, field_14476, field_14476, false);
					this.fillWithOutline(iWorld, mutableIntBoundingBox, var11, 0, 14, var11, 2, 14, field_14476, field_14476, false);
					var11 = 14;
				}

				this.fillWithOutline(iWorld, mutableIntBoundingBox, 8, 3, 8, 8, 3, 13, field_14474, field_14474, false);
				this.fillWithOutline(iWorld, mutableIntBoundingBox, 14, 3, 8, 14, 3, 13, field_14474, field_14474, false);
				this.method_14772(iWorld, mutableIntBoundingBox, 11, 5, 13);
			}

			return true;
		}
	}

	static class class_3388 {
		private final int field_14486;
		private final OceanMonumentGenerator.class_3388[] field_14487 = new OceanMonumentGenerator.class_3388[6];
		private final boolean[] field_14482 = new boolean[6];
		private boolean field_14485;
		private boolean field_14484;
		private int field_14483;

		public class_3388(int i) {
			this.field_14486 = i;
		}

		public void method_14786(Direction direction, OceanMonumentGenerator.class_3388 arg) {
			this.field_14487[direction.getId()] = arg;
			arg.field_14487[direction.getOpposite().getId()] = this;
		}

		public void method_14780() {
			for (int i = 0; i < 6; i++) {
				this.field_14482[i] = this.field_14487[i] != null;
			}
		}

		public boolean method_14783(int i) {
			if (this.field_14484) {
				return true;
			} else {
				this.field_14483 = i;

				for (int j = 0; j < 6; j++) {
					if (this.field_14487[j] != null && this.field_14482[j] && this.field_14487[j].field_14483 != i && this.field_14487[j].method_14783(i)) {
						return true;
					}
				}

				return false;
			}
		}

		public boolean method_14785() {
			return this.field_14486 >= 75;
		}

		public int method_14781() {
			int i = 0;

			for (int j = 0; j < 6; j++) {
				if (this.field_14482[j]) {
					i++;
				}
			}

			return i;
		}
	}
}
